Workbook

Sheet Day-1
A4: Classified Traffic Volume Count Survey - DAY-1 | W4: Classified Traffic Volume Count Survey - DAY-1
A5: Location: | B5: Nathavalasa Toll Plaza | Q5: Date: | R5: 45232 | W5: =A5 -> Location: | X5: =B5 -> Nathavalasa Toll Plaza | AJ5: Date: | AK5: =R5 -> 45232
A6: Direction : | B6: Ranasthalam to Anandapuram | W6: Direction : Both Directions
A7: PCU | B7: 1 | C7: 3 | D7: 1 | E7: 1.5 | F7: 3 | G7: 3 | H7: 4.5 | I7: 4.5 | J7: 0.5 | K7: 1 | L7: 1.5 | M7: 4.5 | N7: 0.5 | O7: 2 | P7: 4.5 | W7: PCU | X7: 1 | Y7: 3 | Z7: 1 | AA7: 1.5 | AB7: 3 | AC7: 3 | AD7: 4.5 | AE7: 4.5 | AF7: 0.5 | AG7: 1 | AH7: 1.5 | AI7: 4.5 | AJ7: 0.5 | AK7: 2 | AL7: 4.5
A8: Time | B8: Motorized Vehicles | N8: Non Motorized | W8: Time | X8: Motorized Vehicles | AJ8: Non Motorized
B9: Car, Jeep, Van& Taxi | C9: Bus | D9: LMV | E9: LCV | F9: 2Axle | G9: 3Axle | H9: 4-6Axle | I9: 7+ - Axle | J9: 2-Wheeler | K9: 3-Wheeler | L9: Tractor | M9: Tractor with trailor | N9: Cycle | O9: Rickshaw | P9: EME & HCM | Q9: Passenger Vehicles | R9: Freight Vehicles | S9: Total Fast Moving Vehicles | T9: Total Slow Moving Vehicles | U9: Total Vehicles | V9: Total PCU | X9: Car, Jeep, Van& Taxi | Y9: Bus | Z9: LMV | AA9: LCV | AB9: 2Axle | AC9: 3Axle | AD9: 4-6Axle | AE9: 7+ - Axle | AF9: 2-Wheeler | AG9: 3-Wheeler | AH9: Tractor | AI9: Tractor with trailor | AJ9: Cycle | AK9: Rickshaw | AL9: EME & HCM | AM9: Passenger Vehicles | AN9: Freight Vehicles | AO9: Total Fast Moving Vehicles | AP9: Total Slow Moving Vehicles | AQ9: Total Vehicles | AR9: Total PCU
A10: 12:00-13:00 | B10: 238 | C10: 24 | D10: 18 | E10: 18 | F10: 11 | G10: 7 | H10: 50 | I10: 0 | J10: 221 | K10: 52 | L10: 0 | M10: 0 | N10: 3 | O10: 0 | P10: 0 | Q10: =B10+C10+J10+K10+N10+O10 -> 538 | R10: =D10+E10+F10+G10+H10+I10+L10+M10+P10 -> 104 | S10: =Q10+R10 -> 642 | T10: =N10+O10 -> 3 | U10: =SUM(B10:P10) -> 642 | V10: =SUMPRODUCT(B10:P10,$B$7:$P$7) -> 798 | W10: =A10 -> 12:00-13:00 | X10: =B10+B44 -> 459 | Y10: =C10+C44 -> 46 | Z10: =D10+D44 -> 34 | AA10: =E10+E44 -> 32 | AB10: =F10+F44 -> 30 | AC10: =G10+G44 -> 30 | AD10: =H10+H44 -> 100 | AE10: =I10+I44 -> 0 | ... AR10: =V10+V44 -> 1606.5
A11: 13:00-14:00 | B11: 193 | C11: 23 | D11: 15 | E11: 11 | F11: 18 | G11: 15 | H11: 54 | I11: 0 | J11: 205 | K11: 57 | L11: 0 | M11: 0 | N11: 4 | O11: 0 | P11: 0 | Q11: =B11+C11+J11+K11+N11+O11 -> 482 | R11: =D11+E11+F11+G11+H11+I11+L11+M11+P11 -> 113 | S11: =Q11+R11 -> 595 | T11: =N11+O11 -> 4 | U11: =SUM(B11:P11) -> 595 | V11: =SUMPRODUCT(B11:P11,$B$7:$P$7) -> 797 | W11: =A11 -> 13:00-14:00 | X11: =B11+B45 -> 321 | Y11: =C11+C45 -> 47 | Z11: =D11+D45 -> 31 | AA11: =E11+E45 -> 25 | AB11: =F11+F45 -> 32 | AC11: =G11+G45 -> 41 | AD11: =H11+H45 -> 107 | AE11: =I11+I45 -> 0 | ... AR11: =V11+V45 -> 1519.5
A12: 14:00-15:00 | B12: 227 | C12: 22 | D12: 17 | E12: 14 | F12: 14 | G12: 13 | H12: 59 | I12: 0 | J12: 222 | K12: 72 | L12: 0 | M12: 3 | N12: 0 | O12: 0 | P12: 0 | Q12: =B12+C12+J12+K12+N12+O12 -> 543 | R12: =D12+E12+F12+G12+H12+I12+L12+M12+P12 -> 120 | S12: =Q12+R12 -> 663 | T12: =N12+O12 -> 0 | U12: =SUM(B12:P12) -> 663 | V12: =SUMPRODUCT(B12:P12,$B$7:$P$7) -> 874 | W12: =A12 -> 14:00-15:00 | X12: =B12+B46 -> 356 | Y12: =C12+C46 -> 40 | Z12: =D12+D46 -> 40 | AA12: =E12+E46 -> 30 | AB12: =F12+F46 -> 39 | AC12: =G12+G46 -> 43 | AD12: =H12+H46 -> 124 | AE12: =I12+I46 -> 0 | ... AR12: =V12+V46 -> 1676.5
A13: 15:00-16:00 | B13: 265 | C13: 27 | D13: 11 | E13: 11 | F13: 21 | G13: 17 | H13: 42 | I13: 0 | J13: 282 | K13: 71 | L13: 0 | M13: 4 | N13: 0 | O13: 0 | P13: 0 | Q13: =B13+C13+J13+K13+N13+O13 -> 645 | R13: =D13+E13+F13+G13+H13+I13+L13+M13+P13 -> 106 | S13: =Q13+R13 -> 751 | T13: =N13+O13 -> 0 | U13: =SUM(B13:P13) -> 751 | V13: =SUMPRODUCT(B13:P13,$B$7:$P$7) -> 906.5 | W13: =A13 -> 15:00-16:00 | X13: =B13+B47 -> 499 | Y13: =C13+C47 -> 49 | Z13: =D13+D47 -> 24 | AA13: =E13+E47 -> 30 | AB13: =F13+F47 -> 56 | AC13: =G13+G47 -> 45 | AD13: =H13+H47 -> 107 | AE13: =I13+I47 -> 0 | ... AR13: =V13+V47 -> 1887.5
A14: 16:00-17:00 | B14: 216 | C14: 30 | D14: 19 | E14: 13 | F14: 22 | G14: 33 | H14: 65 | I14: 0 | J14: 293 | K14: 42 | L14: 0 | M14: 3 | N14: 0 | O14: 0 | P14: 0 | Q14: =B14+C14+J14+K14+N14+O14 -> 581 | R14: =D14+E14+F14+G14+H14+I14+L14+M14+P14 -> 155 | S14: =Q14+R14 -> 736 | T14: =N14+O14 -> 0 | U14: =SUM(B14:P14) -> 736 | V14: =SUMPRODUCT(B14:P14,$B$7:$P$7) -> 1004 | W14: =A14 -> 16:00-17:00 | X14: =B14+B48 -> 463 | Y14: =C14+C48 -> 48 | Z14: =D14+D48 -> 42 | AA14: =E14+E48 -> 26 | AB14: =F14+F48 -> 41 | AC14: =G14+G48 -> 66 | AD14: =H14+H48 -> 113 | AE14: =I14+I48 -> 0 | ... AR14: =V14+V48 -> 1946.5
A15: 17:00-18:00 | B15: 242 | C15: 28 | D15: 18 | E15: 18 | F15: 12 | G15: 15 | H15: 94 | I15: 0 | J15: 339 | K15: 42 | L15: 0 | M15: 3 | N15: 2 | O15: 0 | P15: 0 | Q15: =B15+C15+J15+K15+N15+O15 -> 653 | R15: =D15+E15+F15+G15+H15+I15+L15+M15+P15 -> 160 | S15: =Q15+R15 -> 813 | T15: =N15+O15 -> 2 | U15: =SUM(B15:P15) -> 813 | V15: =SUMPRODUCT(B15:P15,$B$7:$P$7) -> 1101 | W15: =A15 -> 17:00-18:00 | X15: =B15+B49 -> 546 | Y15: =C15+C49 -> 55 | Z15: =D15+D49 -> 40 | AA15: =E15+E49 -> 48 | AB15: =F15+F49 -> 29 | AC15: =G15+G49 -> 56 | AD15: =H15+H49 -> 144 | AE15: =I15+I49 -> 0 | ... AR15: =V15+V49 -> 2112
A16: 18:00-19:00 | B16: 211 | C16: 22 | D16: 17 | E16: 23 | F16: 18 | G16: 25 | H16: 81 | I16: 0 | J16: 364 | K16: 43 | L16: 0 | M16: 2 | N16: 2 | O16: 0 | P16: 0 | Q16: =B16+C16+J16+K16+N16+O16 -> 642 | R16: =D16+E16+F16+G16+H16+I16+L16+M16+P16 -> 166 | S16: =Q16+R16 -> 808 | T16: =N16+O16 -> 2 | U16: =SUM(B16:P16) -> 808 | V16: =SUMPRODUCT(B16:P16,$B$7:$P$7) -> 1057 | W16: =A16 -> 18:00-19:00 | X16: =B16+B50 -> 496 | Y16: =C16+C50 -> 35 | Z16: =D16+D50 -> 32 | AA16: =E16+E50 -> 50 | AB16: =F16+F50 -> 32 | AC16: =G16+G50 -> 62 | AD16: =H16+H50 -> 153 | AE16: =I16+I50 -> 0 | ... AR16: =V16+V50 -> 2049
A17: 19:00-20:00 | B17: 169 | C17: 22 | D17: 16 | E17: 26 | F17: 13 | G17: 15 | H17: 83 | I17: 0 | J17: 272 | K17: 32 | L17: 0 | M17: 3 | N17: 0 | O17: 0 | P17: 0 | Q17: =B17+C17+J17+K17+N17+O17 -> 495 | R17: =D17+E17+F17+G17+H17+I17+L17+M17+P17 -> 156 | S17: =Q17+R17 -> 651 | T17: =N17+O17 -> 0 | U17: =SUM(B17:P17) -> 651 | V17: =SUMPRODUCT(B17:P17,$B$7:$P$7) -> 929 | W17: =A17 -> 19:00-20:00 | X17: =B17+B51 -> 412 | Y17: =C17+C51 -> 41 | Z17: =D17+D51 -> 37 | AA17: =E17+E51 -> 41 | AB17: =F17+F51 -> 27 | AC17: =G17+G51 -> 47 | AD17: =H17+H51 -> 153 | AE17: =I17+I51 -> 0 | ... AR17: =V17+V51 -> 1835.5
A18: 20:00-21:00 | B18: 164 | C18: 26 | D18: 17 | E18: 21 | F18: 26 | G18: 26 | H18: 81 | I18: 0 | J18: 199 | K18: 17 | L18: 0 | M18: 0 | N18: 0 | O18: 0 | P18: 0 | Q18: =B18+C18+J18+K18+N18+O18 -> 406 | R18: =D18+E18+F18+G18+H18+I18+L18+M18+P18 -> 171 | S18: =Q18+R18 -> 577 | T18: =N18+O18 -> 0 | U18: =SUM(B18:P18) -> 577 | V18: =SUMPRODUCT(B18:P18,$B$7:$P$7) -> 927.5 | W18: =A18 -> 20:00-21:00 | X18: =B18+B52 -> 341 | Y18: =C18+C52 -> 45 | Z18: =D18+D52 -> 24 | AA18: =E18+E52 -> 43 | AB18: =F18+F52 -> 42 | AC18: =G18+G52 -> 53 | AD18: =H18+H52 -> 127 | AE18: =I18+I52 -> 0 | ... AR18: =V18+V52 -> 1608
A19: 21:00-22:00 | B19: 81 | C19: 27 | D19: 21 | E19: 22 | F19: 12 | G19: 17 | H19: 97 | I19: 0 | J19: 114 | K19: 11 | L19: 0 | M19: 0 | N19: 0 | O19: 0 | P19: 0 | Q19: =B19+C19+J19+K19+N19+O19 -> 233 | R19: =D19+E19+F19+G19+H19+I19+L19+M19+P19 -> 169 | S19: =Q19+R19 -> 402 | T19: =N19+O19 -> 0 | U19: =SUM(B19:P19) -> 402 | V19: =SUMPRODUCT(B19:P19,$B$7:$P$7) -> 807.5 | W19: =A19 -> 21:00-22:00 | X19: =B19+B53 -> 208 | Y19: =C19+C53 -> 36 | Z19: =D19+D53 -> 36 | AA19: =E19+E53 -> 46 | AB19: =F19+F53 -> 28 | AC19: =G19+G53 -> 38 | AD19: =H19+H53 -> 152 | AE19: =I19+I53 -> 0 | ... AR19: =V19+V53 -> 1428
A20: 22:00-23:00 | B20: 60 | C20: 11 | D20: 6 | E20: 15 | F20: 11 | G20: 23 | H20: 94 | I20: 0 | J20: 80 | K20: 14 | L20: 2 | M20: 2 | N20: 0 | O20: 0 | P20: 0 | Q20: =B20+C20+J20+K20+N20+O20 -> 165 | R20: =D20+E20+F20+G20+H20+I20+L20+M20+P20 -> 153 | S20: =Q20+R20 -> 318 | T20: =N20+O20 -> 0 | U20: =SUM(B20:P20) -> 318 | V20: =SUMPRODUCT(B20:P20,$B$7:$P$7) -> 712.5 | W20: =A20 -> 22:00-23:00 | X20: =B20+B54 -> 127 | Y20: =C20+C54 -> 16 | Z20: =D20+D54 -> 15 | AA20: =E20+E54 -> 38 | AB20: =F20+F54 -> 25 | AC20: =G20+G54 -> 49 | AD20: =H20+H54 -> 137 | AE20: =I20+I54 -> 0 | ... AR20: =V20+V54 -> 1188
A21: 23:00-00:00 | B21: 34 | C21: 4 | D21: 7 | E21: 13 | F21: 11 | G21: 22 | H21: 75 | I21: 0 | J21: 23 | K21: 2 | L21: 0 | M21: 0 | N21: 0 | O21: 0 | P21: 0 | Q21: =B21+C21+J21+K21+N21+O21 -> 63 | R21: =D21+E21+F21+G21+H21+I21+L21+M21+P21 -> 128 | S21: =Q21+R21 -> 191 | T21: =N21+O21 -> 0 | U21: =SUM(B21:P21) -> 191 | V21: =SUMPRODUCT(B21:P21,$B$7:$P$7) -> 522.5 | W21: =A21 -> 23:00-00:00 | X21: =B21+B55 -> 69 | Y21: =C21+C55 -> 7 | Z21: =D21+D55 -> 13 | AA21: =E21+E55 -> 22 | AB21: =F21+F55 -> 26 | AC21: =G21+G55 -> 44 | AD21: =H21+H55 -> 116 | AE21: =I21+I55 -> 0 | ... AR21: =V21+V55 -> 904.5
... A33: 11:00-12:00 | B33: 170 | C33: 34 | D33: 15 | E33: 27 | F33: 14 | G33: 19 | H33: 62 | I33: 0 | J33: 238 | K33: 62 | L33: 2 | M33: 2 | N33: 0 | O33: 0 | P33: 0 | Q33: =B33+C33+J33+K33+N33+O33 -> 504 | R33: =D33+E33+F33+G33+H33+I33+L33+M33+P33 -> 141 | S33: =Q33+R33 -> 645 | T33: =N33+O33 -> 0 | U33: =SUM(B33:P33) -> 645 | V33: =SUMPRODUCT(B33:P33,$B$7:$P$7) -> 898.5 | W33: =A33 -> 11:00-12:00 | X33: =B33+B67 -> 338 | Y33: =C33+C67 -> 55 | Z33: =D33+D67 -> 41 | AA33: =E33+E67 -> 45 | AB33: =F33+F67 -> 36 | AC33: =G33+G67 -> 52 | AD33: =H33+H67 -> 138 | AE33: =I33+I67 -> 0 | ... AR33: =V33+V67 -> 1827.5
A34: Total | B34: =SUM(B10:B33) -> 3164 | C34: =SUM(C10:C33) -> 436 | D34: =SUM(D10:D33) -> 323 | E34: =SUM(E10:E33) -> 368 | F34: =SUM(F10:F33) -> 353 | G34: =SUM(G10:G33) -> 422 | H34: =SUM(H10:H33) -> 1604 | I34: =SUM(I10:I33) -> 0 | ... V34: =SUM(V10:V33) -> 18175.5 | W34: Total | X34: =SUM(X10:X33) -> 6673 | Y34: =SUM(Y10:Y33) -> 890 | Z34: =SUM(Z10:Z33) -> 657 | AA34: =SUM(AA10:AA33) -> 798 | AB34: =SUM(AB10:AB33) -> 780 | AC34: =SUM(AC10:AC33) -> 1145 | AD34: =SUM(AD10:AD33) -> 2959 | AE34: =SUM(AE10:AE33) -> 0 | ... AR34: =SUM(AR10:AR33) -> 36053.5
A38: Classified Traffic Volume Count Survey - DAY-1
A39: =A5 -> Location: | B39: =B5 -> Nathavalasa Toll Plaza | Q39: Date: | R39: =R5 -> 45232
A40: Direction : | B40: Anandapuram to Ranasthalam
A41: PCU | B41: 1 | C41: 3 | D41: 1 | E41: 1.5 | F41: 3 | G41: 3 | H41: 4.5 | I41: 4.5 | J41: 0.5 | K41: 1 | L41: 1.5 | M41: 4.5 | N41: 0.5 | O41: 2 | P41: 4.5
A42: Time | B42: Motorized Vehicles | N42: Non Motorized
B43: Car, Jeep, Van& Taxi | C43: Bus | D43: LMV | E43: LCV | F43: 2Axle | G43: 3Axle | H43: 4-6Axle | I43: 7+ - Axle | J43: 2-Wheeler | K43: 3-Wheeler | L43: Tractor | M43: Tractor with trailor | N43: Cycle | O43: Rickshaw | P43: EME & HCM | Q43: Passenger Vehicles | R43: Freight Vehicles | S43: Total Fast Moving Vehicles | T43: Total Slow Moving Vehicles | U43: Total Vehicles | V43: Total PCU
A44: =A10 -> 12:00-13:00 | B44: 221 | C44: 22 | D44: 16 | E44: 14 | F44: 19 | G44: 23 | H44: 50 | I44: 0 | J44: 156 | K44: 29 | L44: 2 | M44: 5 | N44: 2 | O44: 0 | P44: 0 | Q44: =B44+C44+J44+K44+N44+O44 -> 430 | R44: =D44+E44+F44+G44+H44+I44+L44+M44+P44 -> 129 | S44: =Q44+R44 -> 559 | T44: =N44+O44 -> 2 | U44: =SUM(B44:P44) -> 559 | V44: =SUMPRODUCT(B44:P44,$B$7:$P$7) -> 808.5
A45: =A11 -> 13:00-14:00 | B45: 128 | C45: 24 | D45: 16 | E45: 14 | F45: 14 | G45: 26 | H45: 53 | I45: 0 | J45: 176 | K45: 30 | L45: 0 | M45: 2 | N45: 0 | O45: 0 | P45: 0 | Q45: =B45+C45+J45+K45+N45+O45 -> 358 | R45: =D45+E45+F45+G45+H45+I45+L45+M45+P45 -> 125 | S45: =Q45+R45 -> 483 | T45: =N45+O45 -> 0 | U45: =SUM(B45:P45) -> 483 | V45: =SUMPRODUCT(B45:P45,$B$7:$P$7) -> 722.5
A46: =A12 -> 14:00-15:00 | B46: 129 | C46: 18 | D46: 23 | E46: 16 | F46: 25 | G46: 30 | H46: 65 | I46: 0 | J46: 140 | K46: 27 | L46: 0 | M46: 4 | N46: 0 | O46: 0 | P46: 0 | Q46: =B46+C46+J46+K46+N46+O46 -> 314 | R46: =D46+E46+F46+G46+H46+I46+L46+M46+P46 -> 163 | S46: =Q46+R46 -> 477 | T46: =N46+O46 -> 0 | U46: =SUM(B46:P46) -> 477 | V46: =SUMPRODUCT(B46:P46,$B$7:$P$7) -> 802.5
A47: =A13 -> 15:00-16:00 | B47: 234 | C47: 22 | D47: 13 | E47: 19 | F47: 35 | G47: 28 | H47: 65 | I47: 0 | J47: 179 | K47: 46 | L47: 3 | M47: 4 | N47: 0 | O47: 0 | P47: 0 | Q47: =B47+C47+J47+K47+N47+O47 -> 481 | R47: =D47+E47+F47+G47+H47+I47+L47+M47+P47 -> 167 | S47: =Q47+R47 -> 648 | T47: =N47+O47 -> 0 | U47: =SUM(B47:P47) -> 648 | V47: =SUMPRODUCT(B47:P47,$B$7:$P$7) -> 981
A48: =A14 -> 16:00-17:00 | B48: 247 | C48: 18 | D48: 23 | E48: 13 | F48: 19 | G48: 33 | H48: 48 | I48: 0 | J48: 326 | K48: 54 | L48: 0 | M48: 2 | N48: 2 | O48: 0 | P48: 0 | Q48: =B48+C48+J48+K48+N48+O48 -> 647 | R48: =D48+E48+F48+G48+H48+I48+L48+M48+P48 -> 138 | S48: =Q48+R48 -> 785 | T48: =N48+O48 -> 2 | U48: =SUM(B48:P48) -> 785 | V48: =SUMPRODUCT(B48:P48,$B$7:$P$7) -> 942.5
A49: =A15 -> 17:00-18:00 | B49: 304 | C49: 27 | D49: 22 | E49: 30 | F49: 17 | G49: 41 | H49: 50 | I49: 0 | J49: 207 | K49: 43 | L49: 3 | M49: 2 | N49: 0 | O49: 0 | P49: 0 | Q49: =B49+C49+J49+K49+N49+O49 -> 581 | R49: =D49+E49+F49+G49+H49+I49+L49+M49+P49 -> 165 | S49: =Q49+R49 -> 746 | T49: =N49+O49 -> 0 | U49: =SUM(B49:P49) -> 746 | V49: =SUMPRODUCT(B49:P49,$B$7:$P$7) -> 1011
A50: =A16 -> 18:00-19:00 | B50: 285 | C50: 13 | D50: 15 | E50: 27 | F50: 14 | G50: 37 | H50: 72 | I50: 0 | J50: 181 | K50: 36 | L50: 0 | M50: 2 | N50: 0 | O50: 0 | P50: 0 | Q50: =B50+C50+J50+K50+N50+O50 -> 515 | R50: =D50+E50+F50+G50+H50+I50+L50+M50+P50 -> 167 | S50: =Q50+R50 -> 682 | T50: =N50+O50 -> 0 | U50: =SUM(B50:P50) -> 682 | V50: =SUMPRODUCT(B50:P50,$B$7:$P$7) -> 992
A51: =A17 -> 19:00-20:00 | B51: 243 | C51: 19 | D51: 21 | E51: 15 | F51: 14 | G51: 32 | H51: 70 | I51: 0 | J51: 176 | K51: 22 | L51: 0 | M51: 0 | N51: 0 | O51: 0 | P51: 0 | Q51: =B51+C51+J51+K51+N51+O51 -> 460 | R51: =D51+E51+F51+G51+H51+I51+L51+M51+P51 -> 152 | S51: =Q51+R51 -> 612 | T51: =N51+O51 -> 0 | U51: =SUM(B51:P51) -> 612 | V51: =SUMPRODUCT(B51:P51,$B$7:$P$7) -> 906.5
A52: =A18 -> 20:00-21:00 | B52: 177 | C52: 19 | D52: 7 | E52: 22 | F52: 16 | G52: 27 | H52: 46 | I52: 0 | J52: 123 | K52: 9 | L52: 0 | M52: 0 | N52: 0 | O52: 0 | P52: 0 | Q52: =B52+C52+J52+K52+N52+O52 -> 328 | R52: =D52+E52+F52+G52+H52+I52+L52+M52+P52 -> 118 | S52: =Q52+R52 -> 446 | T52: =N52+O52 -> 0 | U52: =SUM(B52:P52) -> 446 | V52: =SUMPRODUCT(B52:P52,$B$7:$P$7) -> 680.5
A53: =A19 -> 21:00-22:00 | B53: 127 | C53: 9 | D53: 15 | E53: 24 | F53: 16 | G53: 21 | H53: 55 | I53: 0 | J53: 78 | K53: 8 | L53: 0 | M53: 2 | N53: 2 | O53: 0 | P53: 0 | Q53: =B53+C53+J53+K53+N53+O53 -> 224 | R53: =D53+E53+F53+G53+H53+I53+L53+M53+P53 -> 133 | S53: =Q53+R53 -> 357 | T53: =N53+O53 -> 2 | U53: =SUM(B53:P53) -> 357 | V53: =SUMPRODUCT(B53:P53,$B$7:$P$7) -> 620.5
A54: =A20 -> 22:00-23:00 | B54: 67 | C54: 5 | D54: 9 | E54: 23 | F54: 14 | G54: 26 | H54: 43 | I54: 0 | J54: 59 | K54: 7 | L54: 0 | M54: 0 | N54: 0 | O54: 0 | P54: 0 | Q54: =B54+C54+J54+K54+N54+O54 -> 138 | R54: =D54+E54+F54+G54+H54+I54+L54+M54+P54 -> 115 | S54: =Q54+R54 -> 253 | T54: =N54+O54 -> 0 | U54: =SUM(B54:P54) -> 253 | V54: =SUMPRODUCT(B54:P54,$B$7:$P$7) -> 475.5
A55: =A21 -> 23:00-00:00 | B55: 35 | C55: 3 | D55: 6 | E55: 9 | F55: 15 | G55: 22 | H55: 41 | I55: 0 | J55: 34 | K55: 3 | L55: 2 | M55: 0 | N55: 0 | O55: 0 | P55: 0 | Q55: =B55+C55+J55+K55+N55+O55 -> 75 | R55: =D55+E55+F55+G55+H55+I55+L55+M55+P55 -> 95 | S55: =Q55+R55 -> 170 | T55: =N55+O55 -> 0 | U55: =SUM(B55:P55) -> 170 | V55: =SUMPRODUCT(B55:P55,$B$7:$P$7) -> 382
... A67: =A33 -> 11:00-12:00 | B67: 168 | C67: 21 | D67: 26 | E67: 18 | F67: 22 | G67: 33 | H67: 76 | I67: 0 | J67: 165 | K67: 42 | L67: 0 | M67: 3 | N67: 0 | O67: 0 | P67: 0 | Q67: =B67+C67+J67+K67+N67+O67 -> 396 | R67: =D67+E67+F67+G67+H67+I67+L67+M67+P67 -> 178 | S67: =Q67+R67 -> 574 | T67: =N67+O67 -> 0 | U67: =SUM(B67:P67) -> 574 | V67: =SUMPRODUCT(B67:P67,$B$7:$P$7) -> 929
A68: Total | B68: =SUM(B44:B67) -> 3509 | C68: =SUM(C44:C67) -> 454 | D68: =SUM(D44:D67) -> 334 | E68: =SUM(E44:E67) -> 430 | F68: =SUM(F44:F67) -> 427 | G68: =SUM(G44:G67) -> 723 | H68: =SUM(H44:H67) -> 1355 | I68: =SUM(I44:I67) -> 0 | ... V68: =SUM(V44:V67) -> 17878

Sheet Day-2
A4: Classified Traffic Volume Count Survey - DAY-2 | W4: Classified Traffic Volume Count Survey - DAY-2
A5: Location: | B5: ='Day-1'!B5:P5 -> Nathavalasa Toll Plaza | Q5: Date: | R5: 45233 | W5: =A5 -> Location: | X5: =B5 -> Nathavalasa Toll Plaza | AJ5: Date: | AK5: =R5 -> 45233
A6: Direction | B6: ='Day-1'!B6:V6 -> Ranasthalam to Anandapuram | W6: Direction : Both Directions
A7: PCU | B7: 1 | C7: 3 | D7: 1 | E7: 1.5 | F7: 3 | G7: 3 | H7: 4.5 | I7: 4.5 | J7: 0.5 | K7: 1 | L7: 1.5 | M7: 4.5 | N7: 0.5 | O7: 2 | P7: 4.5 | W7: PCU | X7: 1 | Y7: 3 | Z7: 1 | AA7: 1.5 | AB7: 3 | AC7: 3 | AD7: 4.5 | AE7: 4.5 | AF7: 0.5 | AG7: 1 | AH7: 1.5 | AI7: 4.5 | AJ7: 0.5 | AK7: 2 | AL7: 4.5
A8: Time | B8: Motorized Vehicles | N8: Non Motorized | W8: Time | X8: Motorized Vehicles | AJ8: Non Motorized
B9: Car, Jeep, Van& Taxi | C9: Bus | D9: LMV | E9: LCV | F9: 2Axle | G9: 3Axle | H9: 4-6Axle | I9: 7+ - Axle | J9: 2-Wheeler | K9: 3-Wheeler | L9: Tractor | M9: Tractor with trailor | N9: Cycle | O9: Rickshaw | P9: EME & HCM | Q9: Passenger Vehicles | R9: Freight Vehicles | S9: Total Fast Moving Vehicles | T9: Total Slow Moving Vehicles | U9: Total Vehicles | V9: Total PCU | X9: Car, Jeep, Van& Taxi | Y9: Bus | Z9: LMV | AA9: LCV | AB9: 2Axle | AC9: 3Axle | AD9: 4-6Axle | AE9: 7+ - Axle | AF9: 2-Wheeler | AG9: 3-Wheeler | AH9: Tractor | AI9: Tractor with trailor | AJ9: Cycle | AK9: Rickshaw | AL9: EME & HCM | AM9: Passenger Vehicles | AN9: Freight Vehicles | AO9: Total Fast Moving Vehicles | AP9: Total Slow Moving Vehicles | AQ9: Total Vehicles | AR9: Total PCU
A10: ='Day-1'!A10 -> 12:00-13:00 | B10: 139 | C10: 23 | D10: 17 | E10: 24 | F10: 14 | G10: 21 | H10: 56 | I10: 0 | J10: 142 | K10: 47 | L10: 0 | M10: 2 | N10: 0 | O10: 0 | P10: 0 | Q10: =B10+C10+J10+K10+N10+O10 -> 351 | R10: =D10+E10+F10+G10+H10+I10+L10+M10+P10 -> 134 | S10: =Q10+R10 -> 485 | T10: =N10+O10 -> 0 | U10: =SUM(B10:P10) -> 485 | V10: =SUMPRODUCT(B10:P10,$B$7:$P$7) -> 745 | W10: =A10 -> 12:00-13:00 | X10: =B10+B44 -> 268 | Y10: =C10+C44 -> 41 | Z10: =D10+D44 -> 46 | AA10: =E10+E44 -> 49 | AB10: =F10+F44 -> 36 | AC10: =G10+G44 -> 48 | AD10: =H10+H44 -> 118 | AE10: =I10+I44 -> 0 | ... AR10: =V10+V44 -> 1550
A11: ='Day-1'!A11 -> 13:00-14:00 | B11: 112 | C11: 18 | D11: 18 | E11: 25 | F11: 10 | G11: 17 | H11: 45 | I11: 0 | J11: 113 | K11: 35 | L11: 0 | M11: 4 | N11: 0 | O11: 2 | P11: 0 | Q11: =B11+C11+J11+K11+N11+O11 -> 280 | R11: =D11+E11+F11+G11+H11+I11+L11+M11+P11 -> 119 | S11: =Q11+R11 -> 399 | T11: =N11+O11 -> 2 | U11: =SUM(B11:P11) -> 399 | V11: =SUMPRODUCT(B11:P11,$B$7:$P$7) -> 618.5 | W11: =A11 -> 13:00-14:00 | X11: =B11+B45 -> 236 | Y11: =C11+C45 -> 41 | Z11: =D11+D45 -> 39 | AA11: =E11+E45 -> 48 | AB11: =F11+F45 -> 35 | AC11: =G11+G45 -> 33 | AD11: =H11+H45 -> 87 | AE11: =I11+I45 -> 0 | ... AR11: =V11+V45 -> 1285
A12: ='Day-1'!A12 -> 14:00-15:00 | B12: 132 | C12: 30 | D12: 13 | E12: 5 | F12: 16 | G12: 22 | H12: 44 | I12: 0 | J12: 133 | K12: 27 | L12: 2 | M12: 2 | N12: 0 | O12: 0 | P12: 0 | Q12: =B12+C12+J12+K12+N12+O12 -> 322 | R12: =D12+E12+F12+G12+H12+I12+L12+M12+P12 -> 104 | S12: =Q12+R12 -> 426 | T12: =N12+O12 -> 0 | U12: =SUM(B12:P12) -> 426 | V12: =SUMPRODUCT(B12:P12,$B$7:$P$7) -> 660 | W12: =A12 -> 14:00-15:00 | X12: =B12+B46 -> 282 | Y12: =C12+C46 -> 49 | Z12: =D12+D46 -> 44 | AA12: =E12+E46 -> 35 | AB12: =F12+F46 -> 28 | AC12: =G12+G46 -> 47 | AD12: =H12+H46 -> 87 | AE12: =I12+I46 -> 0 | ... AR12: =V12+V46 -> 1332
A13: ='Day-1'!A13 -> 15:00-16:00 | B13: 162 | C13: 27 | D13: 19 | E13: 22 | F13: 14 | G13: 33 | H13: 55 | I13: 0 | J13: 134 | K13: 38 | L13: 0 | M13: 3 | N13: 0 | O13: 0 | P13: 0 | Q13: =B13+C13+J13+K13+N13+O13 -> 361 | R13: =D13+E13+F13+G13+H13+I13+L13+M13+P13 -> 146 | S13: =Q13+R13 -> 507 | T13: =N13+O13 -> 0 | U13: =SUM(B13:P13) -> 507 | V13: =SUMPRODUCT(B13:P13,$B$7:$P$7) -> 802 | W13: =A13 -> 15:00-16:00 | X13: =B13+B47 -> 337 | Y13: =C13+C47 -> 51 | Z13: =D13+D47 -> 45 | AA13: =E13+E47 -> 50 | AB13: =F13+F47 -> 41 | AC13: =G13+G47 -> 83 | AD13: =H13+H47 -> 111 | AE13: =I13+I47 -> 0 | ... AR13: =V13+V47 -> 1699
A14: ='Day-1'!A14 -> 16:00-17:00 | B14: 196 | C14: 28 | D14: 25 | E14: 23 | F14: 19 | G14: 19 | H14: 56 | I14: 0 | J14: 203 | K14: 46 | L14: 0 | M14: 6 | N14: 0 | O14: 0 | P14: 0 | Q14: =B14+C14+J14+K14+N14+O14 -> 473 | R14: =D14+E14+F14+G14+H14+I14+L14+M14+P14 -> 148 | S14: =Q14+R14 -> 621 | T14: =N14+O14 -> 0 | U14: =SUM(B14:P14) -> 621 | V14: =SUMPRODUCT(B14:P14,$B$7:$P$7) -> 880 | W14: =A14 -> 16:00-17:00 | X14: =B14+B48 -> 359 | Y14: =C14+C48 -> 58 | Z14: =D14+D48 -> 44 | AA14: =E14+E48 -> 53 | AB14: =F14+F48 -> 41 | AC14: =G14+G48 -> 46 | AD14: =H14+H48 -> 120 | AE14: =I14+I48 -> 0 | ... AR14: =V14+V48 -> 1758
A15: ='Day-1'!A15 -> 17:00-18:00 | B15: 194 | C15: 26 | D15: 27 | E15: 26 | F15: 22 | G15: 21 | H15: 66 | I15: 0 | J15: 278 | K15: 48 | L15: 0 | M15: 6 | N15: 0 | O15: 0 | P15: 0 | Q15: =B15+C15+J15+K15+N15+O15 -> 546 | R15: =D15+E15+F15+G15+H15+I15+L15+M15+P15 -> 168 | S15: =Q15+R15 -> 714 | T15: =N15+O15 -> 0 | U15: =SUM(B15:P15) -> 714 | V15: =SUMPRODUCT(B15:P15,$B$7:$P$7) -> 978 | W15: =A15 -> 17:00-18:00 | X15: =B15+B49 -> 363 | Y15: =C15+C49 -> 50 | Z15: =D15+D49 -> 50 | AA15: =E15+E49 -> 53 | AB15: =F15+F49 -> 36 | AC15: =G15+G49 -> 48 | AD15: =H15+H49 -> 123 | AE15: =I15+I49 -> 0 | ... AR15: =V15+V49 -> 1826
A16: ='Day-1'!A16 -> 18:00-19:00 | B16: 202 | C16: 33 | D16: 18 | E16: 31 | F16: 29 | G16: 17 | H16: 79 | I16: 0 | J16: 215 | K16: 27 | L16: 0 | M16: 6 | N16: 0 | O16: 0 | P16: 0 | Q16: =B16+C16+J16+K16+N16+O16 -> 477 | R16: =D16+E16+F16+G16+H16+I16+L16+M16+P16 -> 180 | S16: =Q16+R16 -> 657 | T16: =N16+O16 -> 0 | U16: =SUM(B16:P16) -> 657 | V16: =SUMPRODUCT(B16:P16,$B$7:$P$7) -> 1020.5 | W16: =A16 -> 18:00-19:00 | X16: =B16+B50 -> 333 | Y16: =C16+C50 -> 59 | Z16: =D16+D50 -> 37 | AA16: =E16+E50 -> 58 | AB16: =F16+F50 -> 46 | AC16: =G16+G50 -> 48 | AD16: =H16+H50 -> 146 | AE16: =I16+I50 -> 0 | ... AR16: =V16+V50 -> 1839.5
A17: ='Day-1'!A17 -> 19:00-20:00 | B17: 126 | C17: 27 | D17: 17 | E17: 37 | F17: 18 | G17: 18 | H17: 93 | I17: 0 | J17: 151 | K17: 21 | L17: 0 | M17: 5 | N17: 0 | O17: 0 | P17: 0 | Q17: =B17+C17+J17+K17+N17+O17 -> 325 | R17: =D17+E17+F17+G17+H17+I17+L17+M17+P17 -> 188 | S17: =Q17+R17 -> 513 | T17: =N17+O17 -> 0 | U17: =SUM(B17:P17) -> 513 | V17: =SUMPRODUCT(B17:P17,$B$7:$P$7) -> 925 | W17: =A17 -> 19:00-20:00 | X17: =B17+B51 -> 232 | Y17: =C17+C51 -> 48 | Z17: =D17+D51 -> 30 | AA17: =E17+E51 -> 63 | AB17: =F17+F51 -> 29 | AC17: =G17+G51 -> 37 | AD17: =H17+H51 -> 135 | AE17: =I17+I51 -> 0 | ... AR17: =V17+V51 -> 1554
A18: ='Day-1'!A18 -> 20:00-21:00 | B18: 111 | C18: 29 | D18: 17 | E18: 37 | F18: 22 | G18: 15 | H18: 78 | I18: 0 | J18: 133 | K18: 11 | L18: 0 | M18: 0 | N18: 0 | O18: 0 | P18: 0 | Q18: =B18+C18+J18+K18+N18+O18 -> 284 | R18: =D18+E18+F18+G18+H18+I18+L18+M18+P18 -> 169 | S18: =Q18+R18 -> 453 | T18: =N18+O18 -> 0 | U18: =SUM(B18:P18) -> 453 | V18: =SUMPRODUCT(B18:P18,$B$7:$P$7) -> 810 | W18: =A18 -> 20:00-21:00 | X18: =B18+B52 -> 210 | Y18: =C18+C52 -> 40 | Z18: =D18+D52 -> 36 | AA18: =E18+E52 -> 64 | AB18: =F18+F52 -> 43 | AC18: =G18+G52 -> 30 | AD18: =H18+H52 -> 118 | AE18: =I18+I52 -> 0 | ... AR18: =V18+V52 -> 1370
A19: ='Day-1'!A19 -> 21:00-22:00 | B19: 78 | C19: 23 | D19: 17 | E19: 16 | F19: 23 | G19: 15 | H19: 94 | I19: 0 | J19: 56 | K19: 7 | L19: 0 | M19: 0 | N19: 0 | O19: 0 | P19: 0 | Q19: =B19+C19+J19+K19+N19+O19 -> 164 | R19: =D19+E19+F19+G19+H19+I19+L19+M19+P19 -> 165 | S19: =Q19+R19 -> 329 | T19: =N19+O19 -> 0 | U19: =SUM(B19:P19) -> 329 | V19: =SUMPRODUCT(B19:P19,$B$7:$P$7) -> 760 | W19: =A19 -> 21:00-22:00 | X19: =B19+B53 -> 169 | Y19: =C19+C53 -> 42 | Z19: =D19+D53 -> 36 | AA19: =E19+E53 -> 38 | AB19: =F19+F53 -> 41 | AC19: =G19+G53 -> 40 | AD19: =H19+H53 -> 137 | AE19: =I19+I53 -> 0 | ... AR19: =V19+V53 -> 1341.5
A20: ='Day-1'!A20 -> 22:00-23:00 | B20: 49 | C20: 19 | D20: 8 | E20: 18 | F20: 15 | G20: 18 | H20: 99 | I20: 0 | J20: 51 | K20: 6 | L20: 0 | M20: 0 | N20: 0 | O20: 0 | P20: 0 | Q20: =B20+C20+J20+K20+N20+O20 -> 125 | R20: =D20+E20+F20+G20+H20+I20+L20+M20+P20 -> 158 | S20: =Q20+R20 -> 283 | T20: =N20+O20 -> 0 | U20: =SUM(B20:P20) -> 283 | V20: =SUMPRODUCT(B20:P20,$B$7:$P$7) -> 717 | W20: =A20 -> 22:00-23:00 | X20: =B20+B54 -> 128 | Y20: =C20+C54 -> 30 | Z20: =D20+D54 -> 25 | AA20: =E20+E54 -> 41 | AB20: =F20+F54 -> 21 | AC20: =G20+G54 -> 32 | AD20: =H20+H54 -> 158 | AE20: =I20+I54 -> 0 | ... AR20: =V20+V54 -> 1226
A21: ='Day-1'!A21 -> 23:00-00:00 | B21: 26 | C21: 9 | D21: 7 | E21: 16 | F21: 7 | G21: 11 | H21: 75 | I21: 0 | J21: 25 | K21: 2 | L21: 0 | M21: 0 | N21: 0 | O21: 0 | P21: 0 | Q21: =B21+C21+J21+K21+N21+O21 -> 62 | R21: =D21+E21+F21+G21+H21+I21+L21+M21+P21 -> 116 | S21: =Q21+R21 -> 178 | T21: =N21+O21 -> 0 | U21: =SUM(B21:P21) -> 178 | V21: =SUMPRODUCT(B21:P21,$B$7:$P$7) -> 490 | W21: =A21 -> 23:00-00:00 | X21: =B21+B55 -> 73 | Y21: =C21+C55 -> 12 | Z21: =D21+D55 -> 22 | AA21: =E21+E55 -> 30 | AB21: =F21+F55 -> 22 | AC21: =G21+G55 -> 24 | AD21: =H21+H55 -> 169 | AE21: =I21+I55 -> 0 | ... AR21: =V21+V55 -> 1108
... A33: ='Day-1'!A33 -> 11:00-12:00 | B33: 157 | C33: 26 | D33: 23 | E33: 25 | F33: 13 | G33: 17 | H33: 54 | I33: 0 | J33: 218 | K33: 51 | L33: 0 | M33: 4 | N33: 0 | O33: 0 | P33: 5 | Q33: =B33+C33+J33+K33+N33+O33 -> 452 | R33: =D33+E33+F33+G33+H33+I33+L33+M33+P33 -> 141 | S33: =Q33+R33 -> 593 | T33: =N33+O33 -> 0 | U33: =SUM(B33:P33) -> 593 | V33: =SUMPRODUCT(B33:P33,$B$7:$P$7) -> 829 | W33: =A33 -> 11:00-12:00 | X33: =B33+B67 -> 381 | Y33: =C33+C67 -> 51 | Z33: =D33+D67 -> 56 | AA33: =E33+E67 -> 50 | AB33: =F33+F67 -> 68 | AC33: =G33+G67 -> 49 | AD33: =H33+H67 -> 124 | AE33: =I33+I67 -> 0 | ... AR33: =V33+V67 -> 1974.5
A34: Total | B34: =SUM(B10:B33) -> 2389 | C34: =SUM(C10:C33) -> 451 | D34: =SUM(D10:D33) -> 396 | E34: =SUM(E10:E33) -> 522 | F34: =SUM(F10:F33) -> 362 | G34: =SUM(G10:G33) -> 431 | H34: =SUM(H10:H33) -> 1581 | I34: =SUM(I10:I33) -> 0 | ... V34: =SUM(V10:V33) -> 17017.5 | W34: Total | X34: =SUM(X10:X33) -> 4853 | Y34: =SUM(Y10:Y33) -> 923 | Z34: =SUM(Z10:Z33) -> 833 | AA34: =SUM(AA10:AA33) -> 1047 | AB34: =SUM(AB10:AB33) -> 774 | AC34: =SUM(AC10:AC33) -> 1081 | AD34: =SUM(AD10:AD33) -> 3022 | AE34: =SUM(AE10:AE33) -> 0 | ... AR34: =SUM(AR10:AR33) -> 33855
A38: Classified Traffic Volume Count Survey - DAY-2
A39: =A5 -> Location: | B39: =B5 -> Nathavalasa Toll Plaza | Q39: =Q5 -> Date: | R39: =R5 -> 45233
A40: Direction | B40: ='Day-1'!B40:V40 -> Anandapuram to Ranasthalam
A41: PCU | B41: 1 | C41: 3 | D41: 1 | E41: 1.5 | F41: 3 | G41: 3 | H41: 4.5 | I41: 4.5 | J41: 0.5 | K41: 1 | L41: 1.5 | M41: 4.5 | N41: 0.5 | O41: 2 | P41: 4.5
A42: Time | B42: Motorized Vehicles | N42: Non-Motorized
B43: Car, Jeep, Van& Taxi | C43: Bus | D43: LMV | E43: LCV | F43: 2Axle | G43: 3Axle | H43: 4-6Axle | I43: 7+ - Axle | J43: 2-Wheeler | K43: 3-Wheeler | L43: Tractor | M43: Tractor with trailor | N43: Cycle | O43: Rickshaw | P43: EME & HCM | Q43: Passenger Vehicles | R43: Freight Vehicles | S43: Total Fast Moving Vehicles | T43: Total Slow Moving Vehicles | U43: Total Vehicles | V43: Total PCU
A44: =A10 -> 12:00-13:00 | B44: 129 | C44: 18 | D44: 29 | E44: 25 | F44: 22 | G44: 27 | H44: 62 | I44: 0 | J44: 133 | K44: 45 | L44: 0 | M44: 4 | N44: 0 | O44: 0 | P44: 0 | Q44: =B44+C44+J44+K44+N44+O44 -> 325 | R44: =D44+E44+F44+G44+H44+I44+L44+M44+P44 -> 169 | S44: =Q44+R44 -> 494 | T44: =N44+O44 -> 0 | U44: =SUM(B44:P44) -> 494 | V44: =SUMPRODUCT(B44:P44,$B$7:$P$7) -> 805
A45: =A11 -> 13:00-14:00 | B45: 124 | C45: 23 | D45: 21 | E45: 23 | F45: 25 | G45: 16 | H45: 42 | I45: 0 | J45: 120 | K45: 46 | L45: 0 | M45: 0 | N45: 0 | O45: 0 | P45: 0 | Q45: =B45+C45+J45+K45+N45+O45 -> 313 | R45: =D45+E45+F45+G45+H45+I45+L45+M45+P45 -> 127 | S45: =Q45+R45 -> 440 | T45: =N45+O45 -> 0 | U45: =SUM(B45:P45) -> 440 | V45: =SUMPRODUCT(B45:P45,$B$7:$P$7) -> 666.5
A46: =A12 -> 14:00-15:00 | B46: 150 | C46: 19 | D46: 31 | E46: 30 | F46: 12 | G46: 25 | H46: 43 | I46: 0 | J46: 89 | K46: 31 | L46: 0 | M46: 2 | N46: 0 | O46: 0 | P46: 0 | Q46: =B46+C46+J46+K46+N46+O46 -> 289 | R46: =D46+E46+F46+G46+H46+I46+L46+M46+P46 -> 143 | S46: =Q46+R46 -> 432 | T46: =N46+O46 -> 0 | U46: =SUM(B46:P46) -> 432 | V46: =SUMPRODUCT(B46:P46,$B$7:$P$7) -> 672
A47: =A13 -> 15:00-16:00 | B47: 175 | C47: 24 | D47: 26 | E47: 28 | F47: 27 | G47: 50 | H47: 56 | I47: 0 | J47: 91 | K47: 31 | L47: 0 | M47: 5 | N47: 0 | O47: 0 | P47: 0 | Q47: =B47+C47+J47+K47+N47+O47 -> 321 | R47: =D47+E47+F47+G47+H47+I47+L47+M47+P47 -> 192 | S47: =Q47+R47 -> 513 | T47: =N47+O47 -> 0 | U47: =SUM(B47:P47) -> 513 | V47: =SUMPRODUCT(B47:P47,$B$7:$P$7) -> 897
A48: =A14 -> 16:00-17:00 | B48: 163 | C48: 30 | D48: 19 | E48: 30 | F48: 22 | G48: 27 | H48: 64 | I48: 0 | J48: 140 | K48: 32 | L48: 4 | M48: 4 | N48: 0 | O48: 0 | P48: 0 | Q48: =B48+C48+J48+K48+N48+O48 -> 365 | R48: =D48+E48+F48+G48+H48+I48+L48+M48+P48 -> 170 | S48: =Q48+R48 -> 535 | T48: =N48+O48 -> 0 | U48: =SUM(B48:P48) -> 535 | V48: =SUMPRODUCT(B48:P48,$B$7:$P$7) -> 878
A49: =A15 -> 17:00-18:00 | B49: 169 | C49: 24 | D49: 23 | E49: 27 | F49: 14 | G49: 27 | H49: 57 | I49: 0 | J49: 225 | K49: 38 | L49: 0 | M49: 3 | N49: 0 | O49: 0 | P49: 0 | Q49: =B49+C49+J49+K49+N49+O49 -> 456 | R49: =D49+E49+F49+G49+H49+I49+L49+M49+P49 -> 151 | S49: =Q49+R49 -> 607 | T49: =N49+O49 -> 0 | U49: =SUM(B49:P49) -> 607 | V49: =SUMPRODUCT(B49:P49,$B$7:$P$7) -> 848
A50: =A16 -> 18:00-19:00 | B50: 131 | C50: 26 | D50: 19 | E50: 27 | F50: 17 | G50: 31 | H50: 67 | I50: 0 | J50: 160 | K50: 25 | L50: 0 | M50: 0 | N50: 0 | O50: 0 | P50: 0 | Q50: =B50+C50+J50+K50+N50+O50 -> 342 | R50: =D50+E50+F50+G50+H50+I50+L50+M50+P50 -> 161 | S50: =Q50+R50 -> 503 | T50: =N50+O50 -> 0 | U50: =SUM(B50:P50) -> 503 | V50: =SUMPRODUCT(B50:P50,$B$7:$P$7) -> 819
A51: =A17 -> 19:00-20:00 | B51: 106 | C51: 21 | D51: 13 | E51: 26 | F51: 11 | G51: 19 | H51: 42 | I51: 0 | J51: 228 | K51: 15 | L51: 0 | M51: 0 | N51: 0 | O51: 0 | P51: 0 | Q51: =B51+C51+J51+K51+N51+O51 -> 370 | R51: =D51+E51+F51+G51+H51+I51+L51+M51+P51 -> 111 | S51: =Q51+R51 -> 481 | T51: =N51+O51 -> 0 | U51: =SUM(B51:P51) -> 481 | V51: =SUMPRODUCT(B51:P51,$B$7:$P$7) -> 629
A52: =A18 -> 20:00-21:00 | B52: 99 | C52: 11 | D52: 19 | E52: 27 | F52: 21 | G52: 15 | H52: 40 | I52: 0 | J52: 137 | K52: 12 | L52: 0 | M52: 0 | N52: 0 | O52: 0 | P52: 0 | Q52: =B52+C52+J52+K52+N52+O52 -> 259 | R52: =D52+E52+F52+G52+H52+I52+L52+M52+P52 -> 122 | S52: =Q52+R52 -> 381 | T52: =N52+O52 -> 0 | U52: =SUM(B52:P52) -> 381 | V52: =SUMPRODUCT(B52:P52,$B$7:$P$7) -> 560
A53: =A19 -> 21:00-22:00 | B53: 91 | C53: 19 | D53: 19 | E53: 22 | F53: 18 | G53: 25 | H53: 43 | I53: 0 | J53: 82 | K53: 9 | L53: 0 | M53: 2 | N53: 0 | O53: 0 | P53: 0 | Q53: =B53+C53+J53+K53+N53+O53 -> 201 | R53: =D53+E53+F53+G53+H53+I53+L53+M53+P53 -> 129 | S53: =Q53+R53 -> 330 | T53: =N53+O53 -> 0 | U53: =SUM(B53:P53) -> 330 | V53: =SUMPRODUCT(B53:P53,$B$7:$P$7) -> 581.5
A54: =A20 -> 22:00-23:00 | B54: 79 | C54: 11 | D54: 17 | E54: 23 | F54: 6 | G54: 14 | H54: 59 | I54: 0 | J54: 28 | K54: 6 | L54: 0 | M54: 0 | N54: 0 | O54: 0 | P54: 0 | Q54: =B54+C54+J54+K54+N54+O54 -> 124 | R54: =D54+E54+F54+G54+H54+I54+L54+M54+P54 -> 119 | S54: =Q54+R54 -> 243 | T54: =N54+O54 -> 0 | U54: =SUM(B54:P54) -> 243 | V54: =SUMPRODUCT(B54:P54,$B$7:$P$7) -> 509
A55: =A21 -> 23:00-00:00 | B55: 47 | C55: 3 | D55: 15 | E55: 14 | F55: 15 | G55: 13 | H55: 94 | I55: 0 | J55: 38 | K55: 0 | L55: 0 | M55: 0 | N55: 0 | O55: 0 | P55: 0 | Q55: =B55+C55+J55+K55+N55+O55 -> 88 | R55: =D55+E55+F55+G55+H55+I55+L55+M55+P55 -> 151 | S55: =Q55+R55 -> 239 | T55: =N55+O55 -> 0 | U55: =SUM(B55:P55) -> 239 | V55: =SUMPRODUCT(B55:P55,$B$7:$P$7) -> 618
... A67: =A33 -> 11:00-12:00 | B67: 224 | C67: 25 | D67: 33 | E67: 25 | F67: 55 | G67: 32 | H67: 70 | I67: 0 | J67: 233 | K67: 43 | L67: 0 | M67: 9 | N67: 0 | O67: 0 | P67: 0 | Q67: =B67+C67+J67+K67+N67+O67 -> 525 | R67: =D67+E67+F67+G67+H67+I67+L67+M67+P67 -> 224 | S67: =Q67+R67 -> 749 | T67: =N67+O67 -> 0 | U67: =SUM(B67:P67) -> 749 | V67: =SUMPRODUCT(B67:P67,$B$7:$P$7) -> 1145.5
A68: Total | B68: 2324 | C68: 434 | D68: 405 | E68: 484 | F68: 381 | G68: 607 | H68: 1352 | I68: 0 | J68: 2459 | K68: 463 | L68: 3 | M68: 36 | N68: 5 | O68: 0 | P68: 2 | Q68: =SUM(Q44:Q67) -> 6053 | R68: =SUM(R44:R67) -> 3524 | S68: =SUM(S44:S67) -> 9577 | T68: =SUM(T44:T67) -> 10 | U68: =SUM(U44:U67) -> 9577 | V68: =SUM(V44:V67) -> 16837.5

Sheet Day-3
A4: Classified Traffic Volume Count Survey - DAY-3 | W4: Classified Traffic Volume Count Survey - DAY-3
A5: Location: | B5: ='Day-2'!B5:P5 -> Nathavalasa Toll Plaza | Q5: Date: | R5: 45234 | W5: =A5 -> Location: | X5: =B5 -> Nathavalasa Toll Plaza | AJ5: =Q5 -> Date: | AK5: =R5 -> 45234
A6: Direction : | B6: ='Day-2'!B6:V6 -> Ranasthalam to Anandapuram | W6: Direction : Both Directions
A7: PCU | B7: 1 | C7: 3 | D7: 1 | E7: 1.5 | F7: 3 | G7: 3 | H7: 4.5 | I7: 4.5 | J7: 0.5 | K7: 1 | L7: 1.5 | M7: 4.5 | N7: 0.5 | O7: 2 | P7: 4.5 | W7: PCU | X7: 1 | Y7: 3 | Z7: 1 | AA7: 1.5 | AB7: 3 | AC7: 3 | AD7: 4.5 | AE7: 4.5 | AF7: 0.5 | AG7: 1 | AH7: 1.5 | AI7: 4.5 | AJ7: 0.5 | AK7: 2 | AL7: 4.5
A8: Time | B8: Motorized Vehicles | N8: Non- Motorized | W8: Time | X8: Motorized Vehicles | AJ8: Non Motorized
B9: Car, Jeep, Van& Taxi | C9: Bus | D9: LMV | E9: LCV | F9: 2Axle | G9: 3Axle | H9: 4-6Axle | I9: 7+ - Axle | J9: 2-Wheeler | K9: 3-Wheeler | L9: Tractor | M9: Tractor with trailor | N9: Cycle | O9: Rickshaw | P9: EME & HCM | Q9: Passenger Vehicles | R9: Freight Vehicles | S9: Total Fast Moving Vehicles | T9: Total Slow Moving Vehicles | U9: Total Vehicles | V9: Total PCU | X9: Car, Jeep, Van& Taxi | Y9: Bus | Z9: LMV | AA9: LCV | AB9: 2Axle | AC9: 3Axle | AD9: 4-6Axle | AE9: 7+ - Axle | AF9: 2-Wheeler | AG9: 3-Wheeler | AH9: Tractor | AI9: Tractor with trailor | AJ9: Cycle | AK9: Rickshaw | AL9: EME & HCM | AM9: Passenger Vehicles | AN9: Freight Vehicles | AO9: Total Fast Moving Vehicles | AP9: Total Slow Moving Vehicles | AQ9: Total Vehicles | AR9: Total PCU
A10: ='Day-2'!A10 -> 12:00-13:00 | B10: 127 | C10: 24 | D10: 17 | E10: 25 | F10: 9 | G10: 14 | H10: 60 | I10: 0 | J10: 157 | K10: 45 | L10: 0 | M10: 5 | N10: 0 | O10: 0 | P10: 0 | Q10: =B10+C10+J10+K10+N10+O10 -> 353 | R10: =D10+E10+F10+G10+H10+I10+L10+M10+P10 -> 130 | S10: =Q10+R10 -> 483 | T10: =N10+O10 -> 0 | U10: =SUM(B10:P10) -> 483 | V10: =SUMPRODUCT(B10:P10,$B$7:$P$7) -> 738.5 | W10: =A10 -> 12:00-13:00 | X10: =B10+B44 -> 294 | Y10: =C10+C44 -> 46 | Z10: =D10+D44 -> 44 | AA10: =E10+E44 -> 39 | AB10: =F10+F44 -> 20 | AC10: =G10+G44 -> 39 | AD10: =H10+H44 -> 125 | AE10: =I10+I44 -> 0 | ... AR10: =V10+V44 -> 1553.5
A11: ='Day-2'!A11 -> 13:00-14:00 | B11: 98 | C11: 19 | D11: 22 | E11: 26 | F11: 7 | G11: 17 | H11: 57 | I11: 0 | J11: 129 | K11: 30 | L11: 0 | M11: 2 | N11: 0 | O11: 0 | P11: 0 | Q11: =B11+C11+J11+K11+N11+O11 -> 276 | R11: =D11+E11+F11+G11+H11+I11+L11+M11+P11 -> 131 | S11: =Q11+R11 -> 407 | T11: =N11+O11 -> 0 | U11: =SUM(B11:P11) -> 407 | V11: =SUMPRODUCT(B11:P11,$B$7:$P$7) -> 648 | W11: =A11 -> 13:00-14:00 | X11: =B11+B45 -> 196 | Y11: =C11+C45 -> 48 | Z11: =D11+D45 -> 38 | AA11: =E11+E45 -> 45 | AB11: =F11+F45 -> 21 | AC11: =G11+G45 -> 32 | AD11: =H11+H45 -> 136 | AE11: =I11+I45 -> 0 | ... AR11: =V11+V45 -> 1459
A12: ='Day-2'!A12 -> 14:00-15:00 | B12: 121 | C12: 27 | D12: 15 | E12: 17 | F12: 12 | G12: 13 | H12: 56 | I12: 0 | J12: 140 | K12: 32 | L12: 0 | M12: 2 | N12: 0 | O12: 2 | P12: 2 | Q12: =B12+C12+J12+K12+N12+O12 -> 322 | R12: =D12+E12+F12+G12+H12+I12+L12+M12+P12 -> 117 | S12: =Q12+R12 -> 439 | T12: =N12+O12 -> 2 | U12: =SUM(B12:P12) -> 439 | V12: =SUMPRODUCT(B12:P12,$B$7:$P$7) -> 693.5 | W12: =A12 -> 14:00-15:00 | X12: =B12+B46 -> 210 | Y12: =C12+C46 -> 56 | Z12: =D12+D46 -> 39 | AA12: =E12+E46 -> 36 | AB12: =F12+F46 -> 18 | AC12: =G12+G46 -> 35 | AD12: =H12+H46 -> 141 | AE12: =I12+I46 -> 0 | ... AR12: =V12+V46 -> 1520.5
A13: ='Day-2'!A13 -> 15:00-16:00 | B13: 167 | C13: 26 | D13: 29 | E13: 21 | F13: 14 | G13: 14 | H13: 59 | I13: 0 | J13: 178 | K13: 34 | L13: 0 | M13: 4 | N13: 0 | O13: 3 | P13: 0 | Q13: =B13+C13+J13+K13+N13+O13 -> 408 | R13: =D13+E13+F13+G13+H13+I13+L13+M13+P13 -> 141 | S13: =Q13+R13 -> 549 | T13: =N13+O13 -> 3 | U13: =SUM(B13:P13) -> 549 | V13: =SUMPRODUCT(B13:P13,$B$7:$P$7) -> 802 | W13: =A13 -> 15:00-16:00 | X13: =B13+B47 -> 348 | Y13: =C13+C47 -> 55 | Z13: =D13+D47 -> 41 | AA13: =E13+E47 -> 36 | AB13: =F13+F47 -> 27 | AC13: =G13+G47 -> 29 | AD13: =H13+H47 -> 148 | AE13: =I13+I47 -> 0 | ... AR13: =V13+V47 -> 1739.5
A14: ='Day-2'!A14 -> 16:00-17:00 | B14: 159 | C14: 32 | D14: 24 | E14: 23 | F14: 13 | G14: 26 | H14: 55 | I14: 0 | J14: 208 | K14: 50 | L14: 0 | M14: 3 | N14: 0 | O14: 0 | P14: 0 | Q14: =B14+C14+J14+K14+N14+O14 -> 449 | R14: =D14+E14+F14+G14+H14+I14+L14+M14+P14 -> 144 | S14: =Q14+R14 -> 593 | T14: =N14+O14 -> 0 | U14: =SUM(B14:P14) -> 593 | V14: =SUMPRODUCT(B14:P14,$B$7:$P$7) -> 845.5 | W14: =A14 -> 16:00-17:00 | X14: =B14+B48 -> 364 | Y14: =C14+C48 -> 57 | Z14: =D14+D48 -> 33 | AA14: =E14+E48 -> 34 | AB14: =F14+F48 -> 30 | AC14: =G14+G48 -> 40 | AD14: =H14+H48 -> 110 | AE14: =I14+I48 -> 0 | ... AR14: =V14+V48 -> 1662.5
A15: ='Day-2'!A15 -> 17:00-18:00 | B15: 185 | C15: 30 | D15: 15 | E15: 17 | F15: 12 | G15: 33 | H15: 64 | I15: 0 | J15: 254 | K15: 42 | L15: 0 | M15: 3 | N15: 0 | O15: 0 | P15: 0 | Q15: =B15+C15+J15+K15+N15+O15 -> 511 | R15: =D15+E15+F15+G15+H15+I15+L15+M15+P15 -> 144 | S15: =Q15+R15 -> 655 | T15: =N15+O15 -> 0 | U15: =SUM(B15:P15) -> 655 | V15: =SUMPRODUCT(B15:P15,$B$7:$P$7) -> 921 | W15: =A15 -> 17:00-18:00 | X15: =B15+B49 -> 395 | Y15: =C15+C49 -> 71 | Z15: =D15+D49 -> 26 | AA15: =E15+E49 -> 44 | AB15: =F15+F49 -> 20 | AC15: =G15+G49 -> 47 | AD15: =H15+H49 -> 146 | AE15: =I15+I49 -> 0 | ... AR15: =V15+V49 -> 1905.5
A16: ='Day-2'!A16 -> 18:00-19:00 | B16: 203 | C16: 32 | D16: 27 | E16: 24 | F16: 7 | G16: 26 | H16: 86 | I16: 0 | J16: 261 | K16: 32 | L16: 2 | M16: 6 | N16: 0 | O16: 0 | P16: 0 | Q16: =B16+C16+J16+K16+N16+O16 -> 528 | R16: =D16+E16+F16+G16+H16+I16+L16+M16+P16 -> 178 | S16: =Q16+R16 -> 706 | T16: =N16+O16 -> 0 | U16: =SUM(B16:P16) -> 706 | V16: =SUMPRODUCT(B16:P16,$B$7:$P$7) -> 1040.5 | W16: =A16 -> 18:00-19:00 | X16: =B16+B50 -> 340 | Y16: =C16+C50 -> 53 | Z16: =D16+D50 -> 41 | AA16: =E16+E50 -> 40 | AB16: =F16+F50 -> 19 | AC16: =G16+G50 -> 32 | AD16: =H16+H50 -> 143 | AE16: =I16+I50 -> 0 | ... AR16: =V16+V50 -> 1750
A17: ='Day-2'!A17 -> 19:00-20:00 | B17: 112 | C17: 28 | D17: 22 | E17: 35 | F17: 21 | G17: 33 | H17: 64 | I17: 0 | J17: 170 | K17: 28 | L17: 0 | M17: 2 | N17: 0 | O17: 0 | P17: 0 | Q17: =B17+C17+J17+K17+N17+O17 -> 338 | R17: =D17+E17+F17+G17+H17+I17+L17+M17+P17 -> 177 | S17: =Q17+R17 -> 515 | T17: =N17+O17 -> 0 | U17: =SUM(B17:P17) -> 515 | V17: =SUMPRODUCT(B17:P17,$B$7:$P$7) -> 842.5 | W17: =A17 -> 19:00-20:00 | X17: =B17+B51 -> 270 | Y17: =C17+C51 -> 52 | Z17: =D17+D51 -> 32 | AA17: =E17+E51 -> 66 | AB17: =F17+F51 -> 36 | AC17: =G17+G51 -> 50 | AD17: =H17+H51 -> 134 | AE17: =I17+I51 -> 0 | ... AR17: =V17+V51 -> 1718.5
A18: ='Day-2'!A18 -> 20:00-21:00 | B18: 138 | C18: 27 | D18: 18 | E18: 33 | F18: 22 | G18: 25 | H18: 74 | I18: 0 | J18: 158 | K18: 11 | L18: 0 | M18: 7 | N18: 0 | O18: 0 | P18: 0 | Q18: =B18+C18+J18+K18+N18+O18 -> 334 | R18: =D18+E18+F18+G18+H18+I18+L18+M18+P18 -> 179 | S18: =Q18+R18 -> 513 | T18: =N18+O18 -> 0 | U18: =SUM(B18:P18) -> 513 | V18: =SUMPRODUCT(B18:P18,$B$7:$P$7) -> 882 | W18: =A18 -> 20:00-21:00 | X18: =B18+B52 -> 364 | Y18: =C18+C52 -> 56 | Z18: =D18+D52 -> 42 | AA18: =E18+E52 -> 66 | AB18: =F18+F52 -> 48 | AC18: =G18+G52 -> 49 | AD18: =H18+H52 -> 150 | AE18: =I18+I52 -> 0 | ... AR18: =V18+V52 -> 1912.5
A19: ='Day-2'!A19 -> 21:00-22:00 | B19: 82 | C19: 25 | D19: 24 | E19: 28 | F19: 15 | G19: 31 | H19: 71 | I19: 0 | J19: 87 | K19: 11 | L19: 0 | M19: 0 | N19: 0 | O19: 0 | P19: 0 | Q19: =B19+C19+J19+K19+N19+O19 -> 205 | R19: =D19+E19+F19+G19+H19+I19+L19+M19+P19 -> 169 | S19: =Q19+R19 -> 374 | T19: =N19+O19 -> 0 | U19: =SUM(B19:P19) -> 374 | V19: =SUMPRODUCT(B19:P19,$B$7:$P$7) -> 735 | W19: =A19 -> 21:00-22:00 | X19: =B19+B53 -> 227 | Y19: =C19+C53 -> 43 | Z19: =D19+D53 -> 43 | AA19: =E19+E53 -> 45 | AB19: =F19+F53 -> 28 | AC19: =G19+G53 -> 43 | AD19: =H19+H53 -> 155 | AE19: =I19+I53 -> 0 | ... AR19: =V19+V53 -> 1545
A20: ='Day-2'!A20 -> 22:00-23:00 | B20: 32 | C20: 21 | D20: 14 | E20: 29 | F20: 11 | G20: 22 | H20: 57 | I20: 0 | J20: 66 | K20: 9 | L20: 0 | M20: 0 | N20: 0 | O20: 0 | P20: 0 | Q20: =B20+C20+J20+K20+N20+O20 -> 128 | R20: =D20+E20+F20+G20+H20+I20+L20+M20+P20 -> 133 | S20: =Q20+R20 -> 261 | T20: =N20+O20 -> 0 | U20: =SUM(B20:P20) -> 261 | V20: =SUMPRODUCT(B20:P20,$B$7:$P$7) -> 550 | W20: =A20 -> 22:00-23:00 | X20: =B20+B54 -> 118 | Y20: =C20+C54 -> 30 | Z20: =D20+D54 -> 42 | AA20: =E20+E54 -> 51 | AB20: =F20+F54 -> 54 | AC20: =G20+G54 -> 44 | AD20: =H20+H54 -> 122 | AE20: =I20+I54 -> 0 | ... AR20: =V20+V54 -> 1283.5
A21: ='Day-2'!A21 -> 23:00-00:00 | B21: 38 | C21: 11 | D21: 12 | E21: 21 | F21: 6 | G21: 24 | H21: 69 | I21: 0 | J21: 28 | K21: 4 | L21: 0 | M21: 0 | N21: 0 | O21: 0 | P21: 0 | Q21: =B21+C21+J21+K21+N21+O21 -> 81 | R21: =D21+E21+F21+G21+H21+I21+L21+M21+P21 -> 132 | S21: =Q21+R21 -> 213 | T21: =N21+O21 -> 0 | U21: =SUM(B21:P21) -> 213 | V21: =SUMPRODUCT(B21:P21,$B$7:$P$7) -> 533 | W21: =A21 -> 23:00-00:00 | X21: =B21+B55 -> 101 | Y21: =C21+C55 -> 15 | Z21: =D21+D55 -> 23 | AA21: =E21+E55 -> 34 | AB21: =F21+F55 -> 18 | AC21: =G21+G55 -> 46 | AD21: =H21+H55 -> 134 | AE21: =I21+I55 -> 0 | ... AR21: =V21+V55 -> 1065
... A33: ='Day-2'!A33 -> 11:00-12:00 | B33: 191 | C33: 30 | D33: 34 | E33: 13 | F33: 14 | G33: 19 | H33: 67 | I33: 0 | J33: 201 | K33: 65 | L33: 0 | M33: 10 | N33: 0 | O33: 0 | P33: 0 | Q33: =B33+C33+J33+K33+N33+O33 -> 487 | R33: =D33+E33+F33+G33+H33+I33+L33+M33+P33 -> 157 | S33: =Q33+R33 -> 644 | T33: =N33+O33 -> 0 | U33: =SUM(B33:P33) -> 644 | V33: =SUMPRODUCT(B33:P33,$B$7:$P$7) -> 945.5 | W33: =A33 -> 11:00-12:00 | X33: =B33+B67 -> 371 | Y33: =C33+C67 -> 46 | Z33: =D33+D67 -> 45 | AA33: =E33+E67 -> 35 | AB33: =F33+F67 -> 31 | AC33: =G33+G67 -> 52 | AD33: =H33+H67 -> 135 | AE33: =I33+I67 -> 0 | ... AR33: =V33+V67 -> 1853.5
A34: Total | B34: =SUM(B10:B33) -> 2490 | C34: =SUM(C10:C33) -> 465 | D34: =SUM(D10:D33) -> 429 | E34: =SUM(E10:E33) -> 530 | F34: =SUM(F10:F33) -> 280 | G34: =SUM(G10:G33) -> 529 | H34: =SUM(H10:H33) -> 1556 | I34: =SUM(I10:I33) -> 0 | ... V34: =SUM(V10:V33) -> 17218.5 | W34: Total | X34: =SUM(X10:X33) -> 5397 | Y34: =SUM(Y10:Y33) -> 970 | Z34: =SUM(Z10:Z33) -> 791 | AA34: =SUM(AA10:AA33) -> 979 | AB34: =SUM(AB10:AB33) -> 671 | AC34: =SUM(AC10:AC33) -> 1085 | AD34: =SUM(AD10:AD33) -> 3335 | AE34: =SUM(AE10:AE33) -> 0 | ... AR34: =SUM(AR10:AR33) -> 35868.5
A38: Classified Traffic Volume Count Survey - DAY-3
A39: =A5 -> Location: | B39: =B5 -> Nathavalasa Toll Plaza | Q39: =Q5 -> Date: | R39: =R5 -> 45234
A40: Direction : | B40: ='Day-2'!B40:V40 -> Anandapuram to Ranasthalam
A41: PCU | B41: 1 | C41: 3 | D41: 1 | E41: 1.5 | F41: 3 | G41: 3 | H41: 4.5 | I41: 4.5 | J41: 0.5 | K41: 1 | L41: 1.5 | M41: 4.5 | N41: 0.5 | O41: 2 | P41: 4.5
A42: Time | B42: Motorized Vehicles | N42: Non- Motorized
B43: Car, Jeep, Van& Taxi | C43: Bus | D43: LMV | E43: LCV | F43: 2Axle | G43: 3Axle | H43: 4-6Axle | I43: 7+ - Axle | J43: 2-Wheeler | K43: 3-Wheeler | L43: Tractor | M43: Tractor with trailor | N43: Cycle | O43: Rickshaw | P43: EME & HCM | Q43: Passenger Vehicles | R43: Freight Vehicles | S43: Total Fast Moving Vehicles | T43: Total Slow Moving Vehicles | U43: Total Vehicles | V43: Total PCU
A44: =A10 -> 12:00-13:00 | B44: 167 | C44: 22 | D44: 27 | E44: 14 | F44: 11 | G44: 25 | H44: 65 | I44: 0 | J44: 162 | K44: 30 | L44: 0 | M44: 5 | N44: 0 | O44: 0 | P44: 0 | Q44: 0 | R44: 0 | S44: =Q44+R44 -> 0 | T44: =N44+O44 -> 0 | U44: =SUM(B44:P44) -> 528 | V44: =SUMPRODUCT(B44:P44,$B$7:$P$7) -> 815
A45: =A11 -> 13:00-14:00 | B45: 98 | C45: 29 | D45: 16 | E45: 19 | F45: 14 | G45: 15 | H45: 79 | I45: 0 | J45: 176 | K45: 33 | L45: 0 | M45: 4 | N45: 0 | O45: 0 | P45: 0 | Q45: 0 | R45: 0 | S45: =Q45+R45 -> 0 | T45: =N45+O45 -> 0 | U45: =SUM(B45:P45) -> 483 | V45: =SUMPRODUCT(B45:P45,$B$7:$P$7) -> 811
A46: =A12 -> 14:00-15:00 | B46: 89 | C46: 29 | D46: 24 | E46: 19 | F46: 6 | G46: 22 | H46: 85 | I46: 0 | J46: 198 | K46: 29 | L46: 2 | M46: 0 | N46: 2 | O46: 0 | P46: 0 | Q46: 0 | R46: 0 | S46: =Q46+R46 -> 0 | T46: =N46+O46 -> 2 | U46: =SUM(B46:P46) -> 505 | V46: =SUMPRODUCT(B46:P46,$B$7:$P$7) -> 827
A47: =A13 -> 15:00-16:00 | B47: 181 | C47: 29 | D47: 12 | E47: 15 | F47: 13 | G47: 15 | H47: 89 | I47: 0 | J47: 194 | K47: 28 | L47: 2 | M47: 5 | N47: 0 | O47: 0 | P47: 0 | Q47: 0 | R47: 0 | S47: =Q47+R47 -> 0 | T47: =N47+O47 -> 0 | U47: =SUM(B47:P47) -> 583 | V47: =SUMPRODUCT(B47:P47,$B$7:$P$7) -> 937.5
A48: =A14 -> 16:00-17:00 | B48: 205 | C48: 25 | D48: 9 | E48: 11 | F48: 17 | G48: 14 | H48: 55 | I48: 0 | J48: 194 | K48: 56 | L48: 0 | M48: 4 | N48: 0 | O48: 0 | P48: 0 | Q48: 0 | R48: 0 | S48: =Q48+R48 -> 0 | T48: =N48+O48 -> 0 | U48: =SUM(B48:P48) -> 590 | V48: =SUMPRODUCT(B48:P48,$B$7:$P$7) -> 817
A49: =A15 -> 17:00-18:00 | B49: 210 | C49: 41 | D49: 11 | E49: 27 | F49: 8 | G49: 14 | H49: 82 | I49: 0 | J49: 175 | K49: 40 | L49: 4 | M49: 7 | N49: 0 | O49: 0 | P49: 0 | Q49: 0 | R49: 1 | S49: =Q49+R49 -> 1 | T49: =N49+O49 -> 0 | U49: =SUM(B49:P49) -> 619 | V49: =SUMPRODUCT(B49:P49,$B$7:$P$7) -> 984.5
A50: =A16 -> 18:00-19:00 | B50: 137 | C50: 21 | D50: 14 | E50: 16 | F50: 12 | G50: 6 | H50: 57 | I50: 0 | J50: 198 | K50: 26 | L50: 0 | M50: 7 | N50: 0 | O50: 0 | P50: 1 | Q50: 9 | R50: 0 | S50: =Q50+R50 -> 9 | T50: =N50+O50 -> 0 | U50: =SUM(B50:P50) -> 495 | V50: =SUMPRODUCT(B50:P50,$B$7:$P$7) -> 709.5
A51: =A17 -> 19:00-20:00 | B51: 158 | C51: 24 | D51: 10 | E51: 31 | F51: 15 | G51: 17 | H51: 70 | I51: 0 | J51: 281 | K51: 26 | L51: 8 | M51: 0 | N51: 0 | O51: 0 | P51: 0 | Q51: 0 | R51: 2 | S51: =Q51+R51 -> 2 | T51: =N51+O51 -> 0 | U51: =SUM(B51:P51) -> 640 | V51: =SUMPRODUCT(B51:P51,$B$7:$P$7) -> 876
A52: =A18 -> 20:00-21:00 | B52: 226 | C52: 29 | D52: 24 | E52: 33 | F52: 26 | G52: 24 | H52: 76 | I52: 0 | J52: 244 | K52: 24 | L52: 4 | M52: 0 | N52: 0 | O52: 0 | P52: 0 | Q52: 0 | R52: 0 | S52: =Q52+R52 -> 0 | T52: =N52+O52 -> 0 | U52: =SUM(B52:P52) -> 710 | V52: =SUMPRODUCT(B52:P52,$B$7:$P$7) -> 1030.5
A53: =A19 -> 21:00-22:00 | B53: 145 | C53: 18 | D53: 19 | E53: 17 | F53: 13 | G53: 12 | H53: 84 | I53: 0 | J53: 174 | K53: 10 | L53: 2 | M53: 3 | N53: 0 | O53: 0 | P53: 0 | Q53: 0 | R53: 0 | S53: =Q53+R53 -> 0 | T53: =N53+O53 -> 0 | U53: =SUM(B53:P53) -> 497 | V53: =SUMPRODUCT(B53:P53,$B$7:$P$7) -> 810
A54: =A20 -> 22:00-23:00 | B54: 86 | C54: 9 | D54: 28 | E54: 22 | F54: 43 | G54: 22 | H54: 65 | I54: 0 | J54: 94 | K54: 7 | L54: 0 | M54: 4 | N54: 0 | O54: 0 | P54: 0 | Q54: 0 | R54: 0 | S54: =Q54+R54 -> 0 | T54: =N54+O54 -> 0 | U54: =SUM(B54:P54) -> 380 | V54: =SUMPRODUCT(B54:P54,$B$7:$P$7) -> 733.5
A55: =A21 -> 23:00-00:00 | B55: 63 | C55: 4 | D55: 11 | E55: 13 | F55: 12 | G55: 22 | H55: 65 | I55: 0 | J55: 46 | K55: 0 | L55: 0 | M55: 2 | N55: 0 | O55: 0 | P55: 0 | Q55: 0 | R55: 2 | S55: =Q55+R55 -> 2 | T55: =N55+O55 -> 0 | U55: =SUM(B55:P55) -> 238 | V55: =SUMPRODUCT(B55:P55,$B$7:$P$7) -> 532
... A67: =A33 -> 11:00-12:00 | B67: 180 | C67: 16 | D67: 11 | E67: 22 | F67: 17 | G67: 33 | H67: 68 | I67: 0 | J67: 200 | K67: 62 | L67: 0 | M67: 4 | N67: 0 | O67: 0 | P67: 0 | Q67: 0 | R67: 1 | S67: =Q67+R67 -> 1 | T67: =N67+O67 -> 0 | U67: =SUM(B67:P67) -> 613 | V67: =SUMPRODUCT(B67:P67,$B$7:$P$7) -> 908
A68: Total | B68: =SUM(B44:B67) -> 2907 | C68: =SUM(C44:C67) -> 505 | D68: =SUM(D44:D67) -> 362 | E68: =SUM(E44:E67) -> 449 | F68: =SUM(F44:F67) -> 391 | G68: =SUM(G44:G67) -> 556 | H68: =SUM(H44:H67) -> 1779 | I68: =SUM(I44:I67) -> 0 | ... V68: =SUM(V44:V67) -> 18650

Sheet Day-4
A4: Classified Traffic Volume Count Survey - DAY-4 | W4: Classified Traffic Volume Count Survey - DAY-4
A5: Location: | B5: ='Day-3'!B5:P5 -> Nathavalasa Toll Plaza | Q5: Date: | R5: 45235 | W5: =A5 -> Location: | X5: =B5 -> Nathavalasa Toll Plaza | AJ5: =Q5 -> Date: | AK5: =R5 -> 45235
A6: Direction : | B6: ='Day-3'!B6:V6 -> Ranasthalam to Anandapuram | W6: Direction : Both Directions
A7: PCU | B7: 1 | C7: 3 | D7: 1 | E7: 1.5 | F7: 3 | G7: 3 | H7: 4.5 | I7: 4.5 | J7: 0.5 | K7: 1 | L7: 1.5 | M7: 4.5 | N7: 0.5 | O7: 2 | P7: 4.5 | W7: PCU | X7: 1 | Y7: 3 | Z7: 1 | AA7: 1.5 | AB7: 3 | AC7: 3 | AD7: 4.5 | AE7: 4.5 | AF7: 0.5 | AG7: 1 | AH7: 1.5 | AI7: 4.5 | AJ7: 0.5 | AK7: 2 | AL7: 4.5
A8: Time | B8: Motorized Vehicles | N8: Non Motorized | W8: Time | X8: Motorized Vehicles | AJ8: Non Motorized
B9: Car, Jeep, Van& Taxi | C9: Bus | D9: LMV | E9: LCV | F9: 2Axle | G9: 3Axle | H9: 4-6Axle | I9: 7+ - Axle | J9: 2-Wheeler | K9: 3-Wheeler | L9: Tractor | M9: Tractor with trailor | N9: Cycle | O9: Rickshaw | P9: EME & HCM | Q9: Passenger Vehicles | R9: Freight Vehicles | S9: Total Fast Moving Vehicles | T9: Total Slow Moving Vehicles | U9: Total Vehicles | V9: Total PCU | X9: Car, Jeep, Van& Taxi | Y9: Bus | Z9: LMV | AA9: LCV | AB9: 2Axle | AC9: 3Axle | AD9: 4-6Axle | AE9: 7+ - Axle | AF9: 2-Wheeler | AG9: 3-Wheeler | AH9: Tractor | AI9: Tractor with trailor | AJ9: Cycle | AK9: Rickshaw | AL9: EME & HCM | AM9: Passenger Vehicles | AN9: Freight Vehicles | AO9: Total Fast Moving Vehicles | AP9: Total Slow Moving Vehicles | AQ9: Total Vehicles | AR9: Total PCU
A10: ='Day-3'!A10 -> 12:00-13:00 | B10: 176 | C10: 25 | D10: 23 | E10: 21 | F10: 19 | G10: 27 | H10: 66 | I10: 0 | J10: 187 | K10: 51 | L10: 0 | M10: 6 | N10: 0 | O10: 0 | P10: 0 | Q10: =B10+C10+J10+K10+N10+O10 -> 439 | R10: =D10+E10+F10+G10+H10+I10+L10+M10+P10 -> 162 | S10: =Q10+R10 -> 601 | T10: =N10+O10 -> 0 | U10: =SUM(B10:P10) -> 601 | V10: =SUMPRODUCT(B10:P10,$B$7:$P$7) -> 912 | W10: =A10 -> 12:00-13:00 | X10: =B10+B44 -> 337 | Y10: =C10+C44 -> 48 | Z10: =D10+D44 -> 53 | AA10: =E10+E44 -> 34 | AB10: =F10+F44 -> 36 | AC10: =G10+G44 -> 56 | AD10: =H10+H44 -> 132 | AE10: =I10+I44 -> 0 | ... AR10: =V10+V44 -> 1805.5
A11: ='Day-3'!A11 -> 13:00-14:00 | B11: 136 | C11: 23 | D11: 30 | E11: 14 | F11: 19 | G11: 25 | H11: 50 | I11: 0 | J11: 153 | K11: 43 | L11: 0 | M11: 4 | N11: 0 | O11: 0 | P11: 0 | Q11: =B11+C11+J11+K11+N11+O11 -> 355 | R11: =D11+E11+F11+G11+H11+I11+L11+M11+P11 -> 142 | S11: =Q11+R11 -> 497 | T11: =N11+O11 -> 0 | U11: =SUM(B11:P11) -> 497 | V11: =SUMPRODUCT(B11:P11,$B$7:$P$7) -> 750.5 | W11: =A11 -> 13:00-14:00 | X11: =B11+B45 -> 270 | Y11: =C11+C45 -> 56 | Z11: =D11+D45 -> 46 | AA11: =E11+E45 -> 30 | AB11: =F11+F45 -> 33 | AC11: =G11+G45 -> 43 | AD11: =H11+H45 -> 105 | AE11: =I11+I45 -> 0 | ... AR11: =V11+V45 -> 1548.5
A12: ='Day-3'!A12 -> 14:00-15:00 | B12: 189 | C12: 28 | D12: 14 | E12: 15 | F12: 14 | G12: 15 | H12: 61 | I12: 0 | J12: 203 | K12: 52 | L12: 2 | M12: 5 | N12: 3 | O12: 0 | P12: 0 | Q12: =B12+C12+J12+K12+N12+O12 -> 475 | R12: =D12+E12+F12+G12+H12+I12+L12+M12+P12 -> 126 | S12: =Q12+R12 -> 601 | T12: =N12+O12 -> 3 | U12: =SUM(B12:P12) -> 601 | V12: =SUMPRODUCT(B12:P12,$B$7:$P$7) -> 851.5 | W12: =A12 -> 14:00-15:00 | X12: =B12+B46 -> 316 | Y12: =C12+C46 -> 49 | Z12: =D12+D46 -> 36 | AA12: =E12+E46 -> 38 | AB12: =F12+F46 -> 31 | AC12: =G12+G46 -> 48 | AD12: =H12+H46 -> 99 | AE12: =I12+I46 -> 0 | ... AR12: =V12+V46 -> 1525.5
A13: ='Day-3'!A13 -> 15:00-16:00 | B13: 193 | C13: 27 | D13: 24 | E13: 13 | F13: 14 | G13: 14 | H13: 63 | I13: 0 | J13: 256 | K13: 46 | L13: 0 | M13: 4 | N13: 0 | O13: 0 | P13: 0 | Q13: =B13+C13+J13+K13+N13+O13 -> 522 | R13: =D13+E13+F13+G13+H13+I13+L13+M13+P13 -> 132 | S13: =Q13+R13 -> 654 | T13: =N13+O13 -> 0 | U13: =SUM(B13:P13) -> 654 | V13: =SUMPRODUCT(B13:P13,$B$7:$P$7) -> 877 | W13: =A13 -> 15:00-16:00 | X13: =B13+B47 -> 379 | Y13: =C13+C47 -> 59 | Z13: =D13+D47 -> 54 | AA13: =E13+E47 -> 55 | AB13: =F13+F47 -> 39 | AC13: =G13+G47 -> 49 | AD13: =H13+H47 -> 116 | AE13: =I13+I47 -> 0 | ... AR13: =V13+V47 -> 1801
A14: ='Day-3'!A14 -> 16:00-17:00 | B14: 230 | C14: 37 | D14: 24 | E14: 17 | F14: 18 | G14: 23 | H14: 76 | I14: 0 | J14: 324 | K14: 43 | L14: 0 | M14: 4 | N14: 0 | O14: 0 | P14: 0 | Q14: =B14+C14+J14+K14+N14+O14 -> 634 | R14: =D14+E14+F14+G14+H14+I14+L14+M14+P14 -> 162 | S14: =Q14+R14 -> 796 | T14: =N14+O14 -> 0 | U14: =SUM(B14:P14) -> 796 | V14: =SUMPRODUCT(B14:P14,$B$7:$P$7) -> 1078.5 | W14: =A14 -> 16:00-17:00 | X14: =B14+B48 -> 401 | Y14: =C14+C48 -> 73 | Z14: =D14+D48 -> 50 | AA14: =E14+E48 -> 34 | AB14: =F14+F48 -> 32 | AC14: =G14+G48 -> 50 | AD14: =H14+H48 -> 127 | AE14: =I14+I48 -> 0 | ... AR14: =V14+V48 -> 1925
A15: ='Day-3'!A15 -> 17:00-18:00 | B15: 216 | C15: 30 | D15: 28 | E15: 21 | F15: 21 | G15: 16 | H15: 76 | I15: 0 | J15: 265 | K15: 42 | L15: 0 | M15: 3 | N15: 0 | O15: 0 | P15: 1 | Q15: =B15+C15+J15+K15+N15+O15 -> 553 | R15: =D15+E15+F15+G15+H15+I15+L15+M15+P15 -> 166 | S15: =Q15+R15 -> 719 | T15: =N15+O15 -> 0 | U15: =SUM(B15:P15) -> 719 | V15: =SUMPRODUCT(B15:P15,$B$7:$P$7) -> 1011 | W15: =A15 -> 17:00-18:00 | X15: =B15+B49 -> 376 | Y15: =C15+C49 -> 52 | Z15: =D15+D49 -> 45 | AA15: =E15+E49 -> 50 | AB15: =F15+F49 -> 44 | AC15: =G15+G49 -> 41 | AD15: =H15+H49 -> 142 | AE15: =I15+I49 -> 0 | ... AR15: =V15+V49 -> 1894
A16: ='Day-3'!A16 -> 18:00-19:00 | B16: 200 | C16: 41 | D16: 24 | E16: 26 | F16: 27 | G16: 19 | H16: 95 | I16: 0 | J16: 221 | K16: 35 | L16: 0 | M16: 0 | N16: 0 | O16: 0 | P16: 0 | Q16: =B16+C16+J16+K16+N16+O16 -> 497 | R16: =D16+E16+F16+G16+H16+I16+L16+M16+P16 -> 191 | S16: =Q16+R16 -> 688 | T16: =N16+O16 -> 0 | U16: =SUM(B16:P16) -> 688 | V16: =SUMPRODUCT(B16:P16,$B$7:$P$7) -> 1097 | W16: =A16 -> 18:00-19:00 | X16: =B16+B50 -> 350 | Y16: =C16+C50 -> 64 | Z16: =D16+D50 -> 45 | AA16: =E16+E50 -> 52 | AB16: =F16+F50 -> 50 | AC16: =G16+G50 -> 40 | AD16: =H16+H50 -> 159 | AE16: =I16+I50 -> 0 | ... AR16: =V16+V50 -> 1986
A17: ='Day-3'!A17 -> 19:00-20:00 | B17: 172 | C17: 28 | D17: 30 | E17: 25 | F17: 26 | G17: 15 | H17: 92 | I17: 0 | J17: 182 | K17: 38 | L17: 0 | M17: 3 | N17: 0 | O17: 0 | P17: 0 | Q17: =B17+C17+J17+K17+N17+O17 -> 420 | R17: =D17+E17+F17+G17+H17+I17+L17+M17+P17 -> 191 | S17: =Q17+R17 -> 611 | T17: =N17+O17 -> 0 | U17: =SUM(B17:P17) -> 611 | V17: =SUMPRODUCT(B17:P17,$B$7:$P$7) -> 1003 | W17: =A17 -> 19:00-20:00 | X17: =B17+B51 -> 308 | Y17: =C17+C51 -> 50 | Z17: =D17+D51 -> 40 | AA17: =E17+E51 -> 40 | AB17: =F17+F51 -> 45 | AC17: =G17+G51 -> 38 | AD17: =H17+H51 -> 141 | AE17: =I17+I51 -> 0 | ... AR17: =V17+V51 -> 1674
A18: ='Day-3'!A18 -> 20:00-21:00 | B18: 102 | C18: 27 | D18: 19 | E18: 30 | F18: 32 | G18: 21 | H18: 85 | I18: 0 | J18: 56 | K18: 19 | L18: 0 | M18: 0 | N18: 0 | O18: 0 | P18: 0 | Q18: =B18+C18+J18+K18+N18+O18 -> 204 | R18: =D18+E18+F18+G18+H18+I18+L18+M18+P18 -> 187 | S18: =Q18+R18 -> 391 | T18: =N18+O18 -> 0 | U18: =SUM(B18:P18) -> 391 | V18: =SUMPRODUCT(B18:P18,$B$7:$P$7) -> 835.5 | W18: =A18 -> 20:00-21:00 | X18: =B18+B52 -> 229 | Y18: =C18+C52 -> 42 | Z18: =D18+D52 -> 36 | AA18: =E18+E52 -> 41 | AB18: =F18+F52 -> 50 | AC18: =G18+G52 -> 34 | AD18: =H18+H52 -> 131 | AE18: =I18+I52 -> 0 | ... AR18: =V18+V52 -> 1402.5
A19: ='Day-3'!A19 -> 21:00-22:00 | B19: 91 | C19: 33 | D19: 27 | E19: 38 | F19: 45 | G19: 19 | H19: 127 | I19: 0 | J19: 105 | K19: 11 | L19: 0 | M19: 2 | N19: 0 | O19: 0 | P19: 0 | Q19: =B19+C19+J19+K19+N19+O19 -> 240 | R19: =D19+E19+F19+G19+H19+I19+L19+M19+P19 -> 258 | S19: =Q19+R19 -> 498 | T19: =N19+O19 -> 0 | U19: =SUM(B19:P19) -> 498 | V19: =SUMPRODUCT(B19:P19,$B$7:$P$7) -> 1110 | W19: =A19 -> 21:00-22:00 | X19: =B19+B53 -> 218 | Y19: =C19+C53 -> 49 | Z19: =D19+D53 -> 32 | AA19: =E19+E53 -> 45 | AB19: =F19+F53 -> 73 | AC19: =G19+G53 -> 40 | AD19: =H19+H53 -> 171 | AE19: =I19+I53 -> 0 | ... AR19: =V19+V53 -> 1692
A20: ='Day-3'!A20 -> 22:00-23:00 | B20: 40 | C20: 23 | D20: 17 | E20: 25 | F20: 24 | G20: 21 | H20: 97 | I20: 0 | J20: 40 | K20: 11 | L20: 0 | M20: 0 | N20: 0 | O20: 0 | P20: 0 | Q20: =B20+C20+J20+K20+N20+O20 -> 114 | R20: =D20+E20+F20+G20+H20+I20+L20+M20+P20 -> 184 | S20: =Q20+R20 -> 298 | T20: =N20+O20 -> 0 | U20: =SUM(B20:P20) -> 298 | V20: =SUMPRODUCT(B20:P20,$B$7:$P$7) -> 766 | W20: =A20 -> 22:00-23:00 | X20: =B20+B54 -> 128 | Y20: =C20+C54 -> 30 | Z20: =D20+D54 -> 28 | AA20: =E20+E54 -> 53 | AB20: =F20+F54 -> 60 | AC20: =G20+G54 -> 56 | AD20: =H20+H54 -> 139 | AE20: =I20+I54 -> 0 | ... AR20: =V20+V54 -> 1350
A21: ='Day-3'!A21 -> 23:00-00:00 | B21: 27 | C21: 17 | D21: 14 | E21: 21 | F21: 17 | G21: 12 | H21: 74 | I21: 0 | J21: 15 | K21: 6 | L21: 0 | M21: 0 | N21: 0 | O21: 0 | P21: 0 | Q21: =B21+C21+J21+K21+N21+O21 -> 65 | R21: =D21+E21+F21+G21+H21+I21+L21+M21+P21 -> 138 | S21: =Q21+R21 -> 203 | T21: =N21+O21 -> 0 | U21: =SUM(B21:P21) -> 203 | V21: =SUMPRODUCT(B21:P21,$B$7:$P$7) -> 557 | W21: =A21 -> 23:00-00:00 | X21: =B21+B55 -> 90 | Y21: =C21+C55 -> 19 | Z21: =D21+D55 -> 23 | AA21: =E21+E55 -> 37 | AB21: =F21+F55 -> 52 | AC21: =G21+G55 -> 35 | AD21: =H21+H55 -> 111 | AE21: =I21+I55 -> 0 | ... AR21: =V21+V55 -> 1013.5
... A33: ='Day-3'!A33 -> 11:00-12:00 | B33: 179 | C33: 24 | D33: 25 | E33: 32 | F33: 13 | G33: 17 | H33: 62 | I33: 0 | J33: 185 | K33: 44 | L33: 0 | M33: 5 | N33: 0 | O33: 2 | P33: 0 | Q33: =B33+C33+J33+K33+N33+O33 -> 434 | R33: =D33+E33+F33+G33+H33+I33+L33+M33+P33 -> 154 | S33: =Q33+R33 -> 588 | T33: =N33+O33 -> 2 | U33: =SUM(B33:P33) -> 588 | V33: =SUMPRODUCT(B33:P33,$B$7:$P$7) -> 856 | W33: =A33 -> 11:00-12:00 | X33: =B33+B67 -> 337 | Y33: =C33+C67 -> 48 | Z33: =D33+D67 -> 50 | AA33: =E33+E67 -> 51 | AB33: =F33+F67 -> 38 | AC33: =G33+G67 -> 40 | AD33: =H33+H67 -> 131 | AE33: =I33+I67 -> 0 | ... AR33: =V33+V67 -> 1727
A34: Total | B34: =SUM(B10:B33) -> 2695 | C34: =SUM(C10:C33) -> 510 | D34: =SUM(D10:D33) -> 436 | E34: =SUM(E10:E33) -> 446 | F34: =SUM(F10:F33) -> 478 | G34: =SUM(G10:G33) -> 444 | H34: =SUM(H10:H33) -> 1766 | I34: =SUM(I10:I33) -> 0 | ... V34: =SUM(V10:V33) -> 18668 | W34: Total | X34: =SUM(X10:X33) -> 5325 | Y34: =SUM(Y10:Y33) -> 986 | Z34: =SUM(Z10:Z33) -> 797 | AA34: =SUM(AA10:AA33) -> 918 | AB34: =SUM(AB10:AB33) -> 1070 | AC34: =SUM(AC10:AC33) -> 1081 | AD34: =SUM(AD10:AD33) -> 3071 | AE34: =SUM(AE10:AE33) -> 0 | ... AR34: =SUM(AR10:AR33) -> 35563
A38: Classified Traffic Volume Count Survey - DAY-4
A39: =A5 -> Location: | B39: =B5 -> Nathavalasa Toll Plaza | Q39: =Q5 -> Date: | R39: =R5 -> 45235
A40: Direction | B40: ='Day-3'!B40:V40 -> Anandapuram to Ranasthalam
A41: PCU | B41: 1 | C41: 3 | D41: 1 | E41: 1.5 | F41: 3 | G41: 3 | H41: 4.5 | I41: 4.5 | J41: 0.5 | K41: 1 | L41: 1.5 | M41: 4.5 | N41: 0.5 | O41: 2 | P41: 4.5
A42: Time | B42: Motorized Vehicles | N42: Non Motorized
B43: Car, Jeep, Van& Taxi | C43: Bus | D43: LMV | E43: LCV | F43: 2Axle | G43: 3Axle | H43: 4-6Axle | I43: 7+ - Axle | J43: 2-Wheeler | K43: 3-Wheeler | L43: Tractor | M43: Tractor with trailor | N43: Cycle | O43: Rickshaw | P43: EME & HCM | Q43: Passenger Vehicles | R43: Freight Vehicles | S43: Total Fast Moving Vehicles | T43: Total Slow Moving Vehicles | U43: Total Vehicles | V43: Total PCU
A44: =A10 -> 12:00-13:00 | B44: 161 | C44: 23 | D44: 30 | E44: 13 | F44: 17 | G44: 29 | H44: 66 | I44: 0 | J44: 222 | K44: 59 | L44: 0 | M44: 2 | N44: 0 | O44: 0 | P44: 0 | Q44: =B44+C44+J44+K44+N44+O44 -> 465 | R44: =D44+E44+F44+G44+H44+I44+L44+M44+P44 -> 157 | S44: =Q44+R44 -> 622 | T44: =N44+O44 -> 0 | U44: =SUM(B44:P44) -> 622 | V44: =SUMPRODUCT(B44:P44,$B$7:$P$7) -> 893.5
A45: =A11 -> 13:00-14:00 | B45: 134 | C45: 33 | D45: 16 | E45: 16 | F45: 14 | G45: 18 | H45: 55 | I45: 0 | J45: 239 | K45: 44 | L45: 0 | M45: 4 | N45: 0 | O45: 0 | P45: 0 | Q45: =B45+C45+J45+K45+N45+O45 -> 450 | R45: =D45+E45+F45+G45+H45+I45+L45+M45+P45 -> 123 | S45: =Q45+R45 -> 573 | T45: =N45+O45 -> 0 | U45: =SUM(B45:P45) -> 573 | V45: =SUMPRODUCT(B45:P45,$B$7:$P$7) -> 798
A46: =A12 -> 14:00-15:00 | B46: 127 | C46: 21 | D46: 22 | E46: 23 | F46: 17 | G46: 33 | H46: 38 | I46: 0 | J46: 143 | K46: 35 | L46: 0 | M46: 0 | N46: 0 | O46: 0 | P46: 0 | Q46: =B46+C46+J46+K46+N46+O46 -> 326 | R46: =D46+E46+F46+G46+H46+I46+L46+M46+P46 -> 133 | S46: =Q46+R46 -> 459 | T46: =N46+O46 -> 0 | U46: =SUM(B46:P46) -> 459 | V46: =SUMPRODUCT(B46:P46,$B$7:$P$7) -> 674
